Workbook

Sheet LISEZMOI
A1: Vestis — Analyse FEC multi-exercices
A2: Exercices : 2024, 2025. Généré le 19/10/2026.
A4: Principe | B4: Toutes les agrégations sont des formules : modifier le référentiel, une surcharge de compte ou le type d'un journal met à jour tout le classeur. Excel recalcule à l'ouverture ; un aperçu (messagerie, téléphone) peut afficher des cellules vides.
A5: Chaîne de calcul | B5: FEC_xxxx (données) → Comptes (soldes et affectation par exercice) → Liasse (rapprochement) → PnL_annuel, PnL_mensuel, Bilan_synth, Tresorerie.
A6: Où intervenir | B6: Referentiel : colonnes C à F. Comptes : colonnes D et E (jaunes) pour une exception propre au dossier. Journaux : colonne E. Bilan_synth : taux de TVA.
A7: Couleurs | B7: Bleu = donnée saisie ou lue automatiquement ; noir = formule ; fond jaune = hypothèse ou surcharge.
A8: Signes | B8: Compte de résultat : produits positifs, charges négatives. Bilan : fournisseurs et trésorerie en négatif.
A9: Valeurs figées | B9: Onglet Tiers, et dans Controles : écritures déséquilibrées, postes ouverts, continuité. Calculés par l'application ; relancer l'application si un FEC change.
A10: Ordre de lecture | B10: 1. Controles (tout doit être OK) 2. Liasse 3. PnL_annuel 4. Cloture (qualité du résultat) 5. Bilan_synth 6. PnL_mensuel, Tresorerie, Tiers.
A11: Clôture | B11: Cloture : ce que les écritures d'inventaire apportent au résultat, provisions, comptes de régularisation, produits sans encaissement. Ecritures_cloture : liste des écritures, avec un statut et un commentaire à renseigner (colonnes jaunes) ; la synthèse se recalcule sur cette liste.
A12: Confidentialité | B12: Classeur produit localement : les fichiers n'ont été transmis à aucun serveur.

Sheet Pieces_a_demander
A1: Pièces à demander à la société
A2: Liste établie à partir de ce que révèlent les comptes. Colonnes E et F (jaunes) : suivi des demandes.
A4: Domaine | B4: Pièce | C4: Pourquoi / détail | D4: Statut | E4: Demandée le | F4: Reçue le
A5: Comptabilité | B5: FEC des 3 derniers exercices clos | C5: 2 exercice(s) clos fourni(s) | D5: Incomplet
A6: Comptabilité | B6: FEC de l'exercice en cours (situation récente) | D6: À demander
A7: Comptabilité | B7: Liasses fiscales des exercices clos | C7: 0 liasse(s) lue(s) sur 2 | D7: Incomplet
A8: Trésorerie | B8: Relevés bancaires PDF + export CSV, tous comptes, 12 derniers mois | C8: Comptes : 512000 Banque Fictive | D8: À demander
A9: Social | B9: URSSAF : attestation de vigilance et situation du compte (dettes, majorations) | C9: Espace en ligne URSSAF de la société | D9: À demander
A10: Social | B10: État mensuel des cotisations par organisme (logiciel de paie) ou récapitulatifs DSN, 12 derniers mois | C10: Base du rapprochement dû / payé | D10: À demander
A11: Fiscal | B11: Relevé du compte fiscal (espace professionnel impots.gouv) : TVA, IS, CFE, CVAE | D11: À demander
A12: Fiscal | B12: Attestation de régularité fiscale | D12: À demander
A13: Fiscal | B13: Déclarations de TVA des 12 derniers mois | C13: Rapprochement TVA déclarée / payée | D13: À demander
A14: Dette financière | B14: Contrats de prêt et tableaux d'amortissement (dont PGE), sûretés | C14: Emprunts au bilan | D14: À demander
A15: Exploitation | B15: Baux et loyers (échéances, garanties, impayés) | C15: Loyers comptabilisés | D15: À demander
A16: Exploitation | B16: État d'inventaire valorisé à la dernière clôture (par article, avec dates de dernier mouvement) | C16: Stock au bilan | D16: À demander
A17: Exploitation | B17: Balance âgée clients et fournisseurs à date (logiciel de gestion) | C17: Validation de l'ancienneté calculée par l'outil | D17: À demander
A18: Groupe | B18: Organigramme juridique, conventions de trésorerie et de refacturation intragroupe | C18: Comptes courants de groupe | D18: À demander

Sheet Controles
A1: Contrôles d'intégrité
A2: Généré le 19/10/2026 par l'application Vestis (traitement local, aucune donnée transmise).
A4: Contrôle | B4: 2024 | C4: Statut | D4: 2025 | E4: Statut | F4: Commentaire
A5: Total débit - total crédit | B5: =ROUND(SUM(FEC_2024!$I:$I)-SUM(FEC_2024!$J:$J),2) | C5: =IF(ISNUMBER(B5),IF(ABS(B5)<=1,"OK","À VOIR"),"n.d.") | D5: =ROUND(SUM(FEC_2025!$I:$I)-SUM(FEC_2025!$J:$J),2) | E5: =IF(ISNUMBER(D5),IF(ABS(D5)<=1,"OK","À VOIR"),"n.d.")
A6: Écritures déséquilibrées (journal + numéro) | B6: 0 | C6: =IF(ISNUMBER(B6),IF(ABS(B6)<=0,"OK","À VOIR"),"n.d.") | D6: 1 | E6: =IF(ISNUMBER(D6),IF(ABS(D6)<=0,"OK","À VOIR"),"n.d.") | F6: Calculé par l'application.
A7: Lignes sans date d'écriture valide | B7: 0 | C7: =IF(ISNUMBER(B7),IF(ABS(B7)<=0,"OK","À VOIR"),"n.d.") | D7: 0 | E7: =IF(ISNUMBER(D7),IF(ABS(D7)<=0,"OK","À VOIR"),"n.d.")
A8: Comptes non affectés par le référentiel | B8: 0 | C8: =IF(ISNUMBER(B8),IF(ABS(B8)<=0,"OK","À VOIR"),"n.d.") | D8: 0 | E8: =IF(ISNUMBER(D8),IF(ABS(D8)<=0,"OK","À VOIR"),"n.d.")
A9: Postes de liasse en écart (> 1 €) | B9: n.d. | C9: =IF(ISNUMBER(B9),IF(ABS(B9)<=0,"OK","À VOIR"),"n.d.") | D9: n.d. | E9: =IF(ISNUMBER(D9),IF(ABS(D9)<=0,"OK","À VOIR"),"n.d.") | F9: Un écart sur une ligne de détail dont les totaux sont OK est une différence de présentation de la liasse, pas une erreur d'affectation.
A10: Résultat net économique - résultat liasse | B10: n.d. | C10: =IF(ISNUMBER(B10),IF(ABS(B10)<=1,"OK","À VOIR"),"n.d.") | D10: n.d. | E10: =IF(ISNUMBER(D10),IF(ABS(D10)<=1,"OK","À VOIR"),"n.d.")
A11: Équilibre du bilan économique | B11: =Bilan_synth!B32 | C11: =IF(ISNUMBER(B11),IF(ABS(B11)<=1,"OK","À VOIR"),"n.d.") | D11: =Bilan_synth!C32 | E11: =IF(ISNUMBER(D11),IF(ABS(D11)<=1,"OK","À VOIR"),"n.d.")
A12: Postes ouverts (lettrage) - soldes clients et fournisseurs | B12: 0 | C12: =IF(ISNUMBER(B12),IF(ABS(B12)<=1,"OK","À VOIR"),"n.d.") | D12: 0 | E12: =IF(ISNUMBER(D12),IF(ABS(D12)<=1,"OK","À VOIR"),"n.d.") | F12: Postes ouverts = non lettrés + lettrages partiels non soldés.
A13: Continuité : à-nouveaux - clôture de l'exercice précédent (écarts cumulés) | B13: n.d. | C13: =IF(ISNUMBER(B13),IF(ABS(B13)<=1,"OK","À VOIR"),"n.d.") | D13: 0 | E13: =IF(ISNUMBER(D13),IF(ABS(D13)<=1,"OK","À VOIR"),"n.d.") | F13: Compare, par racine de compte, la balance de clôture de l'exercice précédent et le journal d'à-nouveaux. Détail ci-dessous.
A14: Écritures validées après le dépôt de la liasse (impact résultat) | B14: n.d. | C14: =IF(ISNUMBER(B14),IF(ABS(B14)<=1,"OK","À VOIR"),"n.d.") | D14: n.d. | E14: =IF(ISNUMBER(D14),IF(ABS(D14)<=1,"OK","À VOIR"),"n.d.") | F14: Compare la colonne ValidDate du FEC à la date de dépôt imprimée sur la liasse. Une écriture passée après le dépôt signifie que le FEC n'est plus celui de la déclaration. « Non mesurable » : le logiciel met la date d'export dans ValidDate. Détail ci-dessous.
A15: Écritures en double : impact sur le résultat | B15: 0 | C15: =IF(ISNUMBER(B15),IF(ABS(B15)<=1,"OK","À VOIR"),"n.d.") | D15: -12000 | E15: =IF(ISNUMBER(D15),IF(ABS(D15)<=1,"OK","À VOIR"),"n.d.") | F15: Écritures identiques (journal, date, lignes) sous des numéros différents : import répété (paie, ventes). Liste ci-dessous. Un petit montant peut être légitime (deux factures identiques le même jour).
A16: Lignes avec compte auxiliaire (CompAuxNum) | B16: 273 | C16: info | D16: 282 | E16: info | F16: 0 = tiers éclatés dans le plan de comptes (401xxx, 411xxx).
A17: Comptes tiers « DIVERS » | B17: 0 | C17: info | D17: 0 | E17: info | F17: Tiers reconstitués à partir du libellé d'écriture.
A18: Capitaux propres - moitié du capital social (négatif = seuil franchi) | B18: =Bilan_synth!B28+Bilan_synth!B29+SUMIFS(Comptes!$F$5:$F$42,Comptes!$A$5:$A$42,"101*")/2 | C18: =IF(B18>=0,"OK","À VOIR") | D18: =Bilan_synth!C28+Bilan_synth!C29+SUMIFS(Comptes!$I$5:$I$42,Comptes!$A$5:$A$42,"101*")/2 | E18: =IF(D18>=0,"OK","À VOIR") | F18: Capitaux propres devenus inférieurs à la moitié du capital social : obligation de consulter les associés dans les 4 mois suivant l'approbation des comptes (C. com. L223-42 / L225-248). À vérifier par le conseil juridique.
A20: Profil des fichiers
A21: Logiciel (saisi)
A22: Fichier FEC | B22: 999000111FEC20241231.txt | D22: 999000111FEC20251231.txt
A23: Période | B23: 01/01/2024 - 31/12/2024 | D23: 01/01/2025 - 31/12/2025
A24: Encodage | B24: UTF-8 | D24: UTF-8
A25: Séparateur | B25: tabulation | D25: tabulation
A26: Séparateur décimal | B26: virgule | D26: virgule
A27: Format des montants | B27: Débit / Crédit | D27: Débit / Crédit
A28: Nombre de colonnes | B28: 18 | D28: 18
A29: Nombre de lignes | B29: 906 | D29: 932
A30: Régime fiscal (liasse) | B30: Régime réel normal (2050-2053) (par défaut, pas de liasse) | D30: Régime réel normal (2050-2053) (par défaut, pas de liasse)
A31: Liasse | B31: non fournie | D31: non fournie
A32: Journaux | B32: AN A-NOUVEAUX, VT VENTES, AC ACHATS, BQ BANQUE, OD OD, SA OD, INV INVENTAIRE | D32: AN A-NOUVEAUX, AC ACHATS, BQ BANQUE, VT VENTES, OD OD, SA OD, INV INVENTAIRE
A34: Continuité 2024 → 2025 : aucun écart
A35: Racine | B35: Clôture 2024 | C35: À-nouveaux 2025 | D35: Écart
A36: 13 racines comparées, toutes identiques.
A38: 2025 : 1 écriture(s) en double, impact résultat -12000 €
A39: Journal | B39: Date | C39: Nb d'exemplaires | D39: N° d'écriture | E39: Libellé | F39: Montant (débit)
A40: AC | B40: 22/05/2025 | C40: 2 | D40: AC00077, AC00078 | E40: Facture Vernis et Finitions F003-2291 | F40: 14400

Sheet PnL_annuel
A1: Compte de résultat économique
A2: En euros. Produits positifs, charges négatives. Agrégats définis dans Referentiel.
A4: Agrégat | B4: 2024 | C4: % CA | D4: 2025 | E4: % CA
A5: Chiffre d'affaires | B5: =-SUMIFS(Comptes!$F$5:$F$42,Comptes!$H$5:$H$42,"CA") | C5: =IF(B$5=0,0,B5/B$5) | D5: =-SUMIFS(Comptes!$I$5:$I$42,Comptes!$K$5:$K$42,"CA") | E5: =IF(D$5=0,0,D5/D$5)
A6: Production stockée et immobilisée | B6: =-SUMIFS(Comptes!$F$5:$F$42,Comptes!$H$5:$H$42,"PRODUCTION_STOCKEE") | C6: =IF(B$5=0,0,B6/B$5) | D6: =-SUMIFS(Comptes!$I$5:$I$42,Comptes!$K$5:$K$42,"PRODUCTION_STOCKEE") | E6: =IF(D$5=0,0,D6/D$5)
A7: Subventions et autres produits d'exploitation | B7: =-SUMIFS(Comptes!$F$5:$F$42,Comptes!$H$5:$H$42,"AUTRES_PRODUITS") | C7: =IF(B$5=0,0,B7/B$5) | D7: =-SUMIFS(Comptes!$I$5:$I$42,Comptes!$K$5:$K$42,"AUTRES_PRODUITS") | E7: =IF(D$5=0,0,D7/D$5)
A8: Production | B8: =B5+B6+B7 | C8: =IF(B$5=0,0,B8/B$5) | D8: =D5+D6+D7 | E8: =IF(D$5=0,0,D8/D$5)
A9: Coûts directs (achats consommés, sous-traitance) | B9: =-SUMIFS(Comptes!$F$5:$F$42,Comptes!$H$5:$H$42,"COUTS_DIRECTS") | C9: =IF(B$5=0,0,B9/B$5) | D9: =-SUMIFS(Comptes!$I$5:$I$42,Comptes!$K$5:$K$42,"COUTS_DIRECTS") | E9: =IF(D$5=0,0,D9/D$5)
A10: Marge brute | B10: =B8+B9 | C10: =IF(B$5=0,0,B10/B$5) | D10: =D8+D9 | E10: =IF(D$5=0,0,D10/D$5)
A11: Charges externes | B11: =-SUMIFS(Comptes!$F$5:$F$42,Comptes!$H$5:$H$42,"CHARGES_EXTERNES") | C11: =IF(B$5=0,0,B11/B$5) | D11: =-SUMIFS(Comptes!$I$5:$I$42,Comptes!$K$5:$K$42,"CHARGES_EXTERNES") | E11: =IF(D$5=0,0,D11/D$5)
A12: Impôts et taxes | B12: =-SUMIFS(Comptes!$F$5:$F$42,Comptes!$H$5:$H$42,"IMPOTS_TAXES") | C12: =IF(B$5=0,0,B12/B$5) | D12: =-SUMIFS(Comptes!$I$5:$I$42,Comptes!$K$5:$K$42,"IMPOTS_TAXES") | E12: =IF(D$5=0,0,D12/D$5)
A13: Frais de personnel | B13: =-SUMIFS(Comptes!$F$5:$F$42,Comptes!$H$5:$H$42,"PERSONNEL") | C13: =IF(B$5=0,0,B13/B$5) | D13: =-SUMIFS(Comptes!$I$5:$I$42,Comptes!$K$5:$K$42,"PERSONNEL") | E13: =IF(D$5=0,0,D13/D$5)
A14: Autres charges de gestion | B14: =-SUMIFS(Comptes!$F$5:$F$42,Comptes!$H$5:$H$42,"AUTRES_CHARGES") | C14: =IF(B$5=0,0,B14/B$5) | D14: =-SUMIFS(Comptes!$I$5:$I$42,Comptes!$K$5:$K$42,"AUTRES_CHARGES") | E14: =IF(D$5=0,0,D14/D$5)
A15: EBITDA (EBE retraité) | B15: =B10+B11+B12+B13+B14 | C15: =IF(B$5=0,0,B15/B$5) | D15: =D10+D11+D12+D13+D14 | E15: =IF(D$5=0,0,D15/D$5)
A16: Dotations nettes aux amortissements et provisions | B16: =-SUMIFS(Comptes!$F$5:$F$42,Comptes!$H$5:$H$42,"DAP_NETTES") | C16: =IF(B$5=0,0,B16/B$5) | D16: =-SUMIFS(Comptes!$I$5:$I$42,Comptes!$K$5:$K$42,"DAP_NETTES") | E16: =IF(D$5=0,0,D16/D$5)
A17: Résultat d'exploitation (EBIT) | B17: =B15+B16 | C17: =IF(B$5=0,0,B17/B$5) | D17: =D15+D16 | E17: =IF(D$5=0,0,D17/D$5)
A18: Résultat financier | B18: =-SUMIFS(Comptes!$F$5:$F$42,Comptes!$H$5:$H$42,"RESULTAT_FIN") | C18: =IF(B$5=0,0,B18/B$5) | D18: =-SUMIFS(Comptes!$I$5:$I$42,Comptes!$K$5:$K$42,"RESULTAT_FIN") | E18: =IF(D$5=0,0,D18/D$5)
A19: Résultat courant avant impôt | B19: =B17+B18 | C19: =IF(B$5=0,0,B19/B$5) | D19: =D17+D18 | E19: =IF(D$5=0,0,D19/D$5)
A20: Résultat exceptionnel | B20: =-SUMIFS(Comptes!$F$5:$F$42,Comptes!$H$5:$H$42,"EXCEPTIONNEL") | C20: =IF(B$5=0,0,B20/B$5) | D20: =-SUMIFS(Comptes!$I$5:$I$42,Comptes!$K$5:$K$42,"EXCEPTIONNEL") | E20: =IF(D$5=0,0,D20/D$5)
A21: Participation des salariés | B21: =-SUMIFS(Comptes!$F$5:$F$42,Comptes!$H$5:$H$42,"PARTICIPATION") | C21: =IF(B$5=0,0,B21/B$5) | D21: =-SUMIFS(Comptes!$I$5:$I$42,Comptes!$K$5:$K$42,"PARTICIPATION") | E21: =IF(D$5=0,0,D21/D$5)
A22: Impôt sur les sociétés | B22: =-SUMIFS(Comptes!$F$5:$F$42,Comptes!$H$5:$H$42,"IS") | C22: =IF(B$5=0,0,B22/B$5) | D22: =-SUMIFS(Comptes!$I$5:$I$42,Comptes!$K$5:$K$42,"IS") | E22: =IF(D$5=0,0,D22/D$5)
A23: Résultat net | B23: =B19+B20+B21+B22 | C23: =IF(B$5=0,0,B23/B$5) | D23: =D19+D20+D21+D22 | E23: =IF(D$5=0,0,D23/D$5)
A25: Contrôle : résultat net - résultat de la liasse (HN ou 310)
A27: Variation du chiffre d'affaires
A28: 2024 → 2025 | D28: =IF(B5=0,0,D5/B5-1)

Sheet PnL_mensuel
A1: Compte de résultat économique mensuel
A2: Comptabilité brute par mois. Les écritures de clôture (en-cours, provisions, charges à payer) et leurs extournes concentrent des montants sur le premier et le dernier mois : utiliser la ligne « hors clôture » pour les tendances.
B3: 2024 | C3: 2024 | D3: 2024 | E3: 2024 | F3: 2024 | G3: 2024 | H3: 2024 | I3: 2024 | J3: 2024 | K3: 2024 | L3: 2024 | M3: 2024 | N3: 2025 | O3: 2025 | P3: 2025 | Q3: 2025 | R3: 2025 | S3: 2025 | T3: 2025 | U3: 2025 | V3: 2025 | W3: 2025 | X3: 2025 | Y3: 2025
A4: Agrégat | B4: 2024-01 | C4: 2024-02 | D4: 2024-03 | E4: 2024-04 | F4: 2024-05 | G4: 2024-06 | H4: 2024-07 | I4: 2024-08 | J4: 2024-09 | K4: 2024-10 | L4: 2024-11 | M4: 2024-12 | N4: 2025-01 | O4: 2025-02 | P4: 2025-03 | Q4: 2025-04 | R4: 2025-05 | S4: 2025-06 | T4: 2025-07 | U4: 2025-08 | V4: 2025-09 | W4: 2025-10 | X4: 2025-11 | Y4: 2025-12
A5: Chiffre d'affaires | B5: =-SUMIFS(FEC_2024!$M:$M,FEC_2024!$P:$P,"CA",FEC_2024!$N:$N,B$4) | C5: =-SUMIFS(FEC_2024!$M:$M,FEC_2024!$P:$P,"CA",FEC_2024!$N:$N,C$4) | D5: =-SUMIFS(FEC_2024!$M:$M,FEC_2024!$P:$P,"CA",FEC_2024!$N:$N,D$4) | E5: =-SUMIFS(FEC_2024!$M:$M,FEC_2024!$P:$P,"CA",FEC_2024!$N:$N,E$4) | F5: =-SUMIFS(FEC_2024!$M:$M,FEC_2024!$P:$P,"CA",FEC_2024!$N:$N,F$4) | G5: =-SUMIFS(FEC_2024!$M:$M,FEC_2024!$P:$P,"CA",FEC_2024!$N:$N,G$4) | H5: =-SUMIFS(FEC_2024!$M:$M,FEC_2024!$P:$P,"CA",FEC_2024!$N:$N,H$4) | I5: =-SUMIFS(FEC_2024!$M:$M,FEC_2024!$P:$P,"CA",FEC_2024!$N:$N,I$4) | ... M5: =-SUMIFS(FEC_2024!$M:$M,FEC_2024!$P:$P,"CA",FEC_2024!$N:$N,M$4) | N5: =-SUMIFS(FEC_2025!$M:$M,FEC_2025!$P:$P,"CA",FEC_2025!$N:$N,N$4) | O5: =-SUMIFS(FEC_2025!$M:$M,FEC_2025!$P:$P,"CA",FEC_2025!$N:$N,O$4) | P5: =-SUMIFS(FEC_2025!$M:$M,FEC_2025!$P:$P,"CA",FEC_2025!$N:$N,P$4) | Q5: =-SUMIFS(FEC_2025!$M:$M,FEC_2025!$P:$P,"CA",FEC_2025!$N:$N,Q$4) | R5: =-SUMIFS(FEC_2025!$M:$M,FEC_2025!$P:$P,"CA",FEC_2025!$N:$N,R$4) | S5: =-SUMIFS(FEC_2025!$M:$M,FEC_2025!$P:$P,"CA",FEC_2025!$N:$N,S$4) | T5: =-SUMIFS(FEC_2025!$M:$M,FEC_2025!$P:$P,"CA",FEC_2025!$N:$N,T$4) | U5: =-SUMIFS(FEC_2025!$M:$M,FEC_2025!$P:$P,"CA",FEC_2025!$N:$N,U$4) | ... Y5: =-SUMIFS(FEC_2025!$M:$M,FEC_2025!$P:$P,"CA",FEC_2025!$N:$N,Y$4)
A6: Production stockée et immobilisée | B6: =-SUMIFS(FEC_2024!$M:$M,FEC_2024!$P:$P,"PRODUCTION_STOCKEE",FEC_2024!$N:$N,B$4) | C6: =-SUMIFS(FEC_2024!$M:$M,FEC_2024!$P:$P,"PRODUCTION_STOCKEE",FEC_2024!$N:$N,C$4) | D6: =-SUMIFS(FEC_2024!$M:$M,FEC_2024!$P:$P,"PRODUCTION_STOCKEE",FEC_2024!$N:$N,D$4) | E6: =-SUMIFS(FEC_2024!$M:$M,FEC_2024!$P:$P,"PRODUCTION_STOCKEE",FEC_2024!$N:$N,E$4) | F6: =-SUMIFS(FEC_2024!$M:$M,FEC_2024!$P:$P,"PRODUCTION_STOCKEE",FEC_2024!$N:$N,F$4) | G6: =-SUMIFS(FEC_2024!$M:$M,FEC_2024!$P:$P,"PRODUCTION_STOCKEE",FEC_2024!$N:$N,G$4) | H6: =-SUMIFS(FEC_2024!$M:$M,FEC_2024!$P:$P,"PRODUCTION_STOCKEE",FEC_2024!$N:$N,H$4) | I6: =-SUMIFS(FEC_2024!$M:$M,FEC_2024!$P:$P,"PRODUCTION_STOCKEE",FEC_2024!$N:$N,I$4) | ... M6: =-SUMIFS(FEC_2024!$M:$M,FEC_2024!$P:$P,"PRODUCTION_STOCKEE",FEC_2024!$N:$N,M$4) | N6: =-SUMIFS(FEC_2025!$M:$M,FEC_2025!$P:$P,"PRODUCTION_STOCKEE",FEC_2025!$N:$N,N$4) | O6: =-SUMIFS(FEC_2025!$M:$M,FEC_2025!$P:$P,"PRODUCTION_STOCKEE",FEC_2025!$N:$N,O$4) | P6: =-SUMIFS(FEC_2025!$M:$M,FEC_2025!$P:$P,"PRODUCTION_STOCKEE",FEC_2025!$N:$N,P$4) | Q6: =-SUMIFS(FEC_2025!$M:$M,FEC_2025!$P:$P,"PRODUCTION_STOCKEE",FEC_2025!$N:$N,Q$4) | R6: =-SUMIFS(FEC_2025!$M:$M,FEC_2025!$P:$P,"PRODUCTION_STOCKEE",FEC_2025!$N:$N,R$4) | S6: =-SUMIFS(FEC_2025!$M:$M,FEC_2025!$P:$P,"PRODUCTION_STOCKEE",FEC_2025!$N:$N,S$4) | T6: =-SUMIFS(FEC_2025!$M:$M,FEC_2025!$P:$P,"PRODUCTION_STOCKEE",FEC_2025!$N:$N,T$4) | U6: =-SUMIFS(FEC_2025!$M:$M,FEC_2025!$P:$P,"PRODUCTION_STOCKEE",FEC_2025!$N:$N,U$4) | ... Y6: =-SUMIFS(FEC_2025!$M:$M,FEC_2025!$P:$P,"PRODUCTION_STOCKEE",FEC_2025!$N:$N,Y$4)
A7: Subventions et autres produits d'exploitation | B7: =-SUMIFS(FEC_2024!$M:$M,FEC_2024!$P:$P,"AUTRES_PRODUITS",FEC_2024!$N:$N,B$4) | C7: =-SUMIFS(FEC_2024!$M:$M,FEC_2024!$P:$P,"AUTRES_PRODUITS",FEC_2024!$N:$N,C$4) | D7: =-SUMIFS(FEC_2024!$M:$M,FEC_2024!$P:$P,"AUTRES_PRODUITS",FEC_2024!$N:$N,D$4) | E7: =-SUMIFS(FEC_2024!$M:$M,FEC_2024!$P:$P,"AUTRES_PRODUITS",FEC_2024!$N:$N,E$4) | F7: =-SUMIFS(FEC_2024!$M:$M,FEC_2024!$P:$P,"AUTRES_PRODUITS",FEC_2024!$N:$N,F$4) | G7: =-SUMIFS(FEC_2024!$M:$M,FEC_2024!$P:$P,"AUTRES_PRODUITS",FEC_2024!$N:$N,G$4) | H7: =-SUMIFS(FEC_2024!$M:$M,FEC_2024!$P:$P,"AUTRES_PRODUITS",FEC_2024!$N:$N,H$4) | I7: =-SUMIFS(FEC_2024!$M:$M,FEC_2024!$P:$P,"AUTRES_PRODUITS",FEC_2024!$N:$N,I$4) | ... M7: =-SUMIFS(FEC_2024!$M:$M,FEC_2024!$P:$P,"AUTRES_PRODUITS",FEC_2024!$N:$N,M$4) | N7: =-SUMIFS(FEC_2025!$M:$M,FEC_2025!$P:$P,"AUTRES_PRODUITS",FEC_2025!$N:$N,N$4) | O7: =-SUMIFS(FEC_2025!$M:$M,FEC_2025!$P:$P,"AUTRES_PRODUITS",FEC_2025!$N:$N,O$4) | P7: =-SUMIFS(FEC_2025!$M:$M,FEC_2025!$P:$P,"AUTRES_PRODUITS",FEC_2025!$N:$N,P$4) | Q7: =-SUMIFS(FEC_2025!$M:$M,FEC_2025!$P:$P,"AUTRES_PRODUITS",FEC_2025!$N:$N,Q$4) | R7: =-SUMIFS(FEC_2025!$M:$M,FEC_2025!$P:$P,"AUTRES_PRODUITS",FEC_2025!$N:$N,R$4) | S7: =-SUMIFS(FEC_2025!$M:$M,FEC_2025!$P:$P,"AUTRES_PRODUITS",FEC_2025!$N:$N,S$4) | T7: =-SUMIFS(FEC_2025!$M:$M,FEC_2025!$P:$P,"AUTRES_PRODUITS",FEC_2025!$N:$N,T$4) | U7: =-SUMIFS(FEC_2025!$M:$M,FEC_2025!$P:$P,"AUTRES_PRODUITS",FEC_2025!$N:$N,U$4) | ... Y7: =-SUMIFS(FEC_2025!$M:$M,FEC_2025!$P:$P,"AUTRES_PRODUITS",FEC_2025!$N:$N,Y$4)
A8: Production | B8: =B5+B6+B7 | C8: =C5+C6+C7 | D8: =D5+D6+D7 | E8: =E5+E6+E7 | F8: =F5+F6+F7 | G8: =G5+G6+G7 | H8: =H5+H6+H7 | I8: =I5+I6+I7 | ... Y8: =Y5+Y6+Y7
A9: Coûts directs (achats consommés, sous-traitance) | B9: =-SUMIFS(FEC_2024!$M:$M,FEC_2024!$P:$P,"COUTS_DIRECTS",FEC_2024!$N:$N,B$4) | C9: =-SUMIFS(FEC_2024!$M:$M,FEC_2024!$P:$P,"COUTS_DIRECTS",FEC_2024!$N:$N,C$4) | D9: =-SUMIFS(FEC_2024!$M:$M,FEC_2024!$P:$P,"COUTS_DIRECTS",FEC_2024!$N:$N,D$4) | E9: =-SUMIFS(FEC_2024!$M:$M,FEC_2024!$P:$P,"COUTS_DIRECTS",FEC_2024!$N:$N,E$4) | F9: =-SUMIFS(FEC_2024!$M:$M,FEC_2024!$P:$P,"COUTS_DIRECTS",FEC_2024!$N:$N,F$4) | G9: =-SUMIFS(FEC_2024!$M:$M,FEC_2024!$P:$P,"COUTS_DIRECTS",FEC_2024!$N:$N,G$4) | H9: =-SUMIFS(FEC_2024!$M:$M,FEC_2024!$P:$P,"COUTS_DIRECTS",FEC_2024!$N:$N,H$4) | I9: =-SUMIFS(FEC_2024!$M:$M,FEC_2024!$P:$P,"COUTS_DIRECTS",FEC_2024!$N:$N,I$4) | ... M9: =-SUMIFS(FEC_2024!$M:$M,FEC_2024!$P:$P,"COUTS_DIRECTS",FEC_2024!$N:$N,M$4) | N9: =-SUMIFS(FEC_2025!$M:$M,FEC_2025!$P:$P,"COUTS_DIRECTS",FEC_2025!$N:$N,N$4) | O9: =-SUMIFS(FEC_2025!$M:$M,FEC_2025!$P:$P,"COUTS_DIRECTS",FEC_2025!$N:$N,O$4) | P9: =-SUMIFS(FEC_2025!$M:$M,FEC_2025!$P:$P,"COUTS_DIRECTS",FEC_2025!$N:$N,P$4) | Q9: =-SUMIFS(FEC_2025!$M:$M,FEC_2025!$P:$P,"COUTS_DIRECTS",FEC_2025!$N:$N,Q$4) | R9: =-SUMIFS(FEC_2025!$M:$M,FEC_2025!$P:$P,"COUTS_DIRECTS",FEC_2025!$N:$N,R$4) | S9: =-SUMIFS(FEC_2025!$M:$M,FEC_2025!$P:$P,"COUTS_DIRECTS",FEC_2025!$N:$N,S$4) | T9: =-SUMIFS(FEC_2025!$M:$M,FEC_2025!$P:$P,"COUTS_DIRECTS",FEC_2025!$N:$N,T$4) | U9: =-SUMIFS(FEC_2025!$M:$M,FEC_2025!$P:$P,"COUTS_DIRECTS",FEC_2025!$N:$N,U$4) | ... Y9: =-SUMIFS(FEC_2025!$M:$M,FEC_2025!$P:$P,"COUTS_DIRECTS",FEC_2025!$N:$N,Y$4)
A10: Marge brute | B10: =B8+B9 | C10: =C8+C9 | D10: =D8+D9 | E10: =E8+E9 | F10: =F8+F9 | G10: =G8+G9 | H10: =H8+H9 | I10: =I8+I9 | ... Y10: =Y8+Y9
A11: Charges externes | B11: =-SUMIFS(FEC_2024!$M:$M,FEC_2024!$P:$P,"CHARGES_EXTERNES",FEC_2024!$N:$N,B$4) | C11: =-SUMIFS(FEC_2024!$M:$M,FEC_2024!$P:$P,"CHARGES_EXTERNES",FEC_2024!$N:$N,C$4) | D11: =-SUMIFS(FEC_2024!$M:$M,FEC_2024!$P:$P,"CHARGES_EXTERNES",FEC_2024!$N:$N,D$4) | E11: =-SUMIFS(FEC_2024!$M:$M,FEC_2024!$P:$P,"CHARGES_EXTERNES",FEC_2024!$N:$N,E$4) | F11: =-SUMIFS(FEC_2024!$M:$M,FEC_2024!$P:$P,"CHARGES_EXTERNES",FEC_2024!$N:$N,F$4) | G11: =-SUMIFS(FEC_2024!$M:$M,FEC_2024!$P:$P,"CHARGES_EXTERNES",FEC_2024!$N:$N,G$4) | H11: =-SUMIFS(FEC_2024!$M:$M,FEC_2024!$P:$P,"CHARGES_EXTERNES",FEC_2024!$N:$N,H$4) | I11: =-SUMIFS(FEC_2024!$M:$M,FEC_2024!$P:$P,"CHARGES_EXTERNES",FEC_2024!$N:$N,I$4) | ... M11: =-SUMIFS(FEC_2024!$M:$M,FEC_2024!$P:$P,"CHARGES_EXTERNES",FEC_2024!$N:$N,M$4) | N11: =-SUMIFS(FEC_2025!$M:$M,FEC_2025!$P:$P,"CHARGES_EXTERNES",FEC_2025!$N:$N,N$4) | O11: =-SUMIFS(FEC_2025!$M:$M,FEC_2025!$P:$P,"CHARGES_EXTERNES",FEC_2025!$N:$N,O$4) | P11: =-SUMIFS(FEC_2025!$M:$M,FEC_2025!$P:$P,"CHARGES_EXTERNES",FEC_2025!$N:$N,P$4) | Q11: =-SUMIFS(FEC_2025!$M:$M,FEC_2025!$P:$P,"CHARGES_EXTERNES",FEC_2025!$N:$N,Q$4) | R11: =-SUMIFS(FEC_2025!$M:$M,FEC_2025!$P:$P,"CHARGES_EXTERNES",FEC_2025!$N:$N,R$4) | S11: =-SUMIFS(FEC_2025!$M:$M,FEC_2025!$P:$P,"CHARGES_EXTERNES",FEC_2025!$N:$N,S$4) | T11: =-SUMIFS(FEC_2025!$M:$M,FEC_2025!$P:$P,"CHARGES_EXTERNES",FEC_2025!$N:$N,T$4) | U11: =-SUMIFS(FEC_2025!$M:$M,FEC_2025!$P:$P,"CHARGES_EXTERNES",FEC_2025!$N:$N,U$4) | ... Y11: =-SUMIFS(FEC_2025!$M:$M,FEC_2025!$P:$P,"CHARGES_EXTERNES",FEC_2025!$N:$N,Y$4)
A12: Impôts et taxes | B12: =-SUMIFS(FEC_2024!$M:$M,FEC_2024!$P:$P,"IMPOTS_TAXES",FEC_2024!$N:$N,B$4) | C12: =-SUMIFS(FEC_2024!$M:$M,FEC_2024!$P:$P,"IMPOTS_TAXES",FEC_2024!$N:$N,C$4) | D12: =-SUMIFS(FEC_2024!$M:$M,FEC_2024!$P:$P,"IMPOTS_TAXES",FEC_2024!$N:$N,D$4) | E12: =-SUMIFS(FEC_2024!$M:$M,FEC_2024!$P:$P,"IMPOTS_TAXES",FEC_2024!$N:$N,E$4) | F12: =-SUMIFS(FEC_2024!$M:$M,FEC_2024!$P:$P,"IMPOTS_TAXES",FEC_2024!$N:$N,F$4) | G12: =-SUMIFS(FEC_2024!$M:$M,FEC_2024!$P:$P,"IMPOTS_TAXES",FEC_2024!$N:$N,G$4) | H12: =-SUMIFS(FEC_2024!$M:$M,FEC_2024!$P:$P,"IMPOTS_TAXES",FEC_2024!$N:$N,H$4) | I12: =-SUMIFS(FEC_2024!$M:$M,FEC_2024!$P:$P,"IMPOTS_TAXES",FEC_2024!$N:$N,I$4) | ... M12: =-SUMIFS(FEC_2024!$M:$M,FEC_2024!$P:$P,"IMPOTS_TAXES",FEC_2024!$N:$N,M$4) | N12: =-SUMIFS(FEC_2025!$M:$M,FEC_2025!$P:$P,"IMPOTS_TAXES",FEC_2025!$N:$N,N$4) | O12: =-SUMIFS(FEC_2025!$M:$M,FEC_2025!$P:$P,"IMPOTS_TAXES",FEC_2025!$N:$N,O$4) | P12: =-SUMIFS(FEC_2025!$M:$M,FEC_2025!$P:$P,"IMPOTS_TAXES",FEC_2025!$N:$N,P$4) | Q12: =-SUMIFS(FEC_2025!$M:$M,FEC_2025!$P:$P,"IMPOTS_TAXES",FEC_2025!$N:$N,Q$4) | R12: =-SUMIFS(FEC_2025!$M:$M,FEC_2025!$P:$P,"IMPOTS_TAXES",FEC_2025!$N:$N,R$4) | S12: =-SUMIFS(FEC_2025!$M:$M,FEC_2025!$P:$P,"IMPOTS_TAXES",FEC_2025!$N:$N,S$4) | T12: =-SUMIFS(FEC_2025!$M:$M,FEC_2025!$P:$P,"IMPOTS_TAXES",FEC_2025!$N:$N,T$4) | U12: =-SUMIFS(FEC_2025!$M:$M,FEC_2025!$P:$P,"IMPOTS_TAXES",FEC_2025!$N:$N,U$4) | ... Y12: =-SUMIFS(FEC_2025!$M:$M,FEC_2025!$P:$P,"IMPOTS_TAXES",FEC_2025!$N:$N,Y$4)
A13: Frais de personnel | B13: =-SUMIFS(FEC_2024!$M:$M,FEC_2024!$P:$P,"PERSONNEL",FEC_2024!$N:$N,B$4) | C13: =-SUMIFS(FEC_2024!$M:$M,FEC_2024!$P:$P,"PERSONNEL",FEC_2024!$N:$N,C$4) | D13: =-SUMIFS(FEC_2024!$M:$M,FEC_2024!$P:$P,"PERSONNEL",FEC_2024!$N:$N,D$4) | E13: =-SUMIFS(FEC_2024!$M:$M,FEC_2024!$P:$P,"PERSONNEL",FEC_2024!$N:$N,E$4) | F13: =-SUMIFS(FEC_2024!$M:$M,FEC_2024!$P:$P,"PERSONNEL",FEC_2024!$N:$N,F$4) | G13: =-SUMIFS(FEC_2024!$M:$M,FEC_2024!$P:$P,"PERSONNEL",FEC_2024!$N:$N,G$4) | H13: =-SUMIFS(FEC_2024!$M:$M,FEC_2024!$P:$P,"PERSONNEL",FEC_2024!$N:$N,H$4) | I13: =-SUMIFS(FEC_2024!$M:$M,FEC_2024!$P:$P,"PERSONNEL",FEC_2024!$N:$N,I$4) | ... M13: =-SUMIFS(FEC_2024!$M:$M,FEC_2024!$P:$P,"PERSONNEL",FEC_2024!$N:$N,M$4) | N13: =-SUMIFS(FEC_2025!$M:$M,FEC_2025!$P:$P,"PERSONNEL",FEC_2025!$N:$N,N$4) | O13: =-SUMIFS(FEC_2025!$M:$M,FEC_2025!$P:$P,"PERSONNEL",FEC_2025!$N:$N,O$4) | P13: =-SUMIFS(FEC_2025!$M:$M,FEC_2025!$P:$P,"PERSONNEL",FEC_2025!$N:$N,P$4) | Q13: =-SUMIFS(FEC_2025!$M:$M,FEC_2025!$P:$P,"PERSONNEL",FEC_2025!$N:$N,Q$4) | R13: =-SUMIFS(FEC_2025!$M:$M,FEC_2025!$P:$P,"PERSONNEL",FEC_2025!$N:$N,R$4) | S13: =-SUMIFS(FEC_2025!$M:$M,FEC_2025!$P:$P,"PERSONNEL",FEC_2025!$N:$N,S$4) | T13: =-SUMIFS(FEC_2025!$M:$M,FEC_2025!$P:$P,"PERSONNEL",FEC_2025!$N:$N,T$4) | U13: =-SUMIFS(FEC_2025!$M:$M,FEC_2025!$P:$P,"PERSONNEL",FEC_2025!$N:$N,U$4) | ... Y13: =-SUMIFS(FEC_2025!$M:$M,FEC_2025!$P:$P,"PERSONNEL",FEC_2025!$N:$N,Y$4)
A14: Autres charges de gestion | B14: =-SUMIFS(FEC_2024!$M:$M,FEC_2024!$P:$P,"AUTRES_CHARGES",FEC_2024!$N:$N,B$4) | C14: =-SUMIFS(FEC_2024!$M:$M,FEC_2024!$P:$P,"AUTRES_CHARGES",FEC_2024!$N:$N,C$4) | D14: =-SUMIFS(FEC_2024!$M:$M,FEC_2024!$P:$P,"AUTRES_CHARGES",FEC_2024!$N:$N,D$4) | E14: =-SUMIFS(FEC_2024!$M:$M,FEC_2024!$P:$P,"AUTRES_CHARGES",FEC_2024!$N:$N,E$4) | F14: =-SUMIFS(FEC_2024!$M:$M,FEC_2024!$P:$P,"AUTRES_CHARGES",FEC_2024!$N:$N,F$4) | G14: =-SUMIFS(FEC_2024!$M:$M,FEC_2024!$P:$P,"AUTRES_CHARGES",FEC_2024!$N:$N,G$4) | H14: =-SUMIFS(FEC_2024!$M:$M,FEC_2024!$P:$P,"AUTRES_CHARGES",FEC_2024!$N:$N,H$4) | I14: =-SUMIFS(FEC_2024!$M:$M,FEC_2024!$P:$P,"AUTRES_CHARGES",FEC_2024!$N:$N,I$4) | ... M14: =-SUMIFS(FEC_2024!$M:$M,FEC_2024!$P:$P,"AUTRES_CHARGES",FEC_2024!$N:$N,M$4) | N14: =-SUMIFS(FEC_2025!$M:$M,FEC_2025!$P:$P,"AUTRES_CHARGES",FEC_2025!$N:$N,N$4) | O14: =-SUMIFS(FEC_2025!$M:$M,FEC_2025!$P:$P,"AUTRES_CHARGES",FEC_2025!$N:$N,O$4) | P14: =-SUMIFS(FEC_2025!$M:$M,FEC_2025!$P:$P,"AUTRES_CHARGES",FEC_2025!$N:$N,P$4) | Q14: =-SUMIFS(FEC_2025!$M:$M,FEC_2025!$P:$P,"AUTRES_CHARGES",FEC_2025!$N:$N,Q$4) | R14: =-SUMIFS(FEC_2025!$M:$M,FEC_2025!$P:$P,"AUTRES_CHARGES",FEC_2025!$N:$N,R$4) | S14: =-SUMIFS(FEC_2025!$M:$M,FEC_2025!$P:$P,"AUTRES_CHARGES",FEC_2025!$N:$N,S$4) | T14: =-SUMIFS(FEC_2025!$M:$M,FEC_2025!$P:$P,"AUTRES_CHARGES",FEC_2025!$N:$N,T$4) | U14: =-SUMIFS(FEC_2025!$M:$M,FEC_2025!$P:$P,"AUTRES_CHARGES",FEC_2025!$N:$N,U$4) | ... Y14: =-SUMIFS(FEC_2025!$M:$M,FEC_2025!$P:$P,"AUTRES_CHARGES",FEC_2025!$N:$N,Y$4)
A15: EBITDA (EBE retraité) | B15: =B10+B11+B12+B13+B14 | C15: =C10+C11+C12+C13+C14 | D15: =D10+D11+D12+D13+D14 | E15: =E10+E11+E12+E13+E14 | F15: =F10+F11+F12+F13+F14 | G15: =G10+G11+G12+G13+G14 | H15: =H10+H11+H12+H13+H14 | I15: =I10+I11+I12+I13+I14 | ... Y15: =Y10+Y11+Y12+Y13+Y14
A16: Dotations nettes aux amortissements et provisions | B16: =-SUMIFS(FEC_2024!$M:$M,FEC_2024!$P:$P,"DAP_NETTES",FEC_2024!$N:$N,B$4) | C16: =-SUMIFS(FEC_2024!$M:$M,FEC_2024!$P:$P,"DAP_NETTES",FEC_2024!$N:$N,C$4) | D16: =-SUMIFS(FEC_2024!$M:$M,FEC_2024!$P:$P,"DAP_NETTES",FEC_2024!$N:$N,D$4) | E16: =-SUMIFS(FEC_2024!$M:$M,FEC_2024!$P:$P,"DAP_NETTES",FEC_2024!$N:$N,E$4) | F16: =-SUMIFS(FEC_2024!$M:$M,FEC_2024!$P:$P,"DAP_NETTES",FEC_2024!$N:$N,F$4) | G16: =-SUMIFS(FEC_2024!$M:$M,FEC_2024!$P:$P,"DAP_NETTES",FEC_2024!$N:$N,G$4) | H16: =-SUMIFS(FEC_2024!$M:$M,FEC_2024!$P:$P,"DAP_NETTES",FEC_2024!$N:$N,H$4) | I16: =-SUMIFS(FEC_2024!$M:$M,FEC_2024!$P:$P,"DAP_NETTES",FEC_2024!$N:$N,I$4) | ... M16: =-SUMIFS(FEC_2024!$M:$M,FEC_2024!$P:$P,"DAP_NETTES",FEC_2024!$N:$N,M$4) | N16: =-SUMIFS(FEC_2025!$M:$M,FEC_2025!$P:$P,"DAP_NETTES",FEC_2025!$N:$N,N$4) | O16: =-SUMIFS(FEC_2025!$M:$M,FEC_2025!$P:$P,"DAP_NETTES",FEC_2025!$N:$N,O$4) | P16: =-SUMIFS(FEC_2025!$M:$M,FEC_2025!$P:$P,"DAP_NETTES",FEC_2025!$N:$N,P$4) | Q16: =-SUMIFS(FEC_2025!$M:$M,FEC_2025!$P:$P,"DAP_NETTES",FEC_2025!$N:$N,Q$4) | R16: =-SUMIFS(FEC_2025!$M:$M,FEC_2025!$P:$P,"DAP_NETTES",FEC_2025!$N:$N,R$4) | S16: =-SUMIFS(FEC_2025!$M:$M,FEC_2025!$P:$P,"DAP_NETTES",FEC_2025!$N:$N,S$4) | T16: =-SUMIFS(FEC_2025!$M:$M,FEC_2025!$P:$P,"DAP_NETTES",FEC_2025!$N:$N,T$4) | U16: =-SUMIFS(FEC_2025!$M:$M,FEC_2025!$P:$P,"DAP_NETTES",FEC_2025!$N:$N,U$4) | ... Y16: =-SUMIFS(FEC_2025!$M:$M,FEC_2025!$P:$P,"DAP_NETTES",FEC_2025!$N:$N,Y$4)
A17: Résultat d'exploitation (EBIT) | B17: =B15+B16 | C17: =C15+C16 | D17: =D15+D16 | E17: =E15+E16 | F17: =F15+F16 | G17: =G15+G16 | H17: =H15+H16 | I17: =I15+I16 | ... Y17: =Y15+Y16
A18: Résultat financier | B18: =-SUMIFS(FEC_2024!$M:$M,FEC_2024!$P:$P,"RESULTAT_FIN",FEC_2024!$N:$N,B$4) | C18: =-SUMIFS(FEC_2024!$M:$M,FEC_2024!$P:$P,"RESULTAT_FIN",FEC_2024!$N:$N,C$4) | D18: =-SUMIFS(FEC_2024!$M:$M,FEC_2024!$P:$P,"RESULTAT_FIN",FEC_2024!$N:$N,D$4) | E18: =-SUMIFS(FEC_2024!$M:$M,FEC_2024!$P:$P,"RESULTAT_FIN",FEC_2024!$N:$N,E$4) | F18: =-SUMIFS(FEC_2024!$M:$M,FEC_2024!$P:$P,"RESULTAT_FIN",FEC_2024!$N:$N,F$4) | G18: =-SUMIFS(FEC_2024!$M:$M,FEC_2024!$P:$P,"RESULTAT_FIN",FEC_2024!$N:$N,G$4) | H18: =-SUMIFS(FEC_2024!$M:$M,FEC_2024!$P:$P,"RESULTAT_FIN",FEC_2024!$N:$N,H$4) | I18: =-SUMIFS(FEC_2024!$M:$M,FEC_2024!$P:$P,"RESULTAT_FIN",FEC_2024!$N:$N,I$4) | ... M18: =-SUMIFS(FEC_2024!$M:$M,FEC_2024!$P:$P,"RESULTAT_FIN",FEC_2024!$N:$N,M$4) | N18: =-SUMIFS(FEC_2025!$M:$M,FEC_2025!$P:$P,"RESULTAT_FIN",FEC_2025!$N:$N,N$4) | O18: =-SUMIFS(FEC_2025!$M:$M,FEC_2025!$P:$P,"RESULTAT_FIN",FEC_2025!$N:$N,O$4) | P18: =-SUMIFS(FEC_2025!$M:$M,FEC_2025!$P:$P,"RESULTAT_FIN",FEC_2025!$N:$N,P$4) | Q18: =-SUMIFS(FEC_2025!$M:$M,FEC_2025!$P:$P,"RESULTAT_FIN",FEC_2025!$N:$N,Q$4) | R18: =-SUMIFS(FEC_2025!$M:$M,FEC_2025!$P:$P,"RESULTAT_FIN",FEC_2025!$N:$N,R$4) | S18: =-SUMIFS(FEC_2025!$M:$M,FEC_2025!$P:$P,"RESULTAT_FIN",FEC_2025!$N:$N,S$4) | T18: =-SUMIFS(FEC_2025!$M:$M,FEC_2025!$P:$P,"RESULTAT_FIN",FEC_2025!$N:$N,T$4) | U18: =-SUMIFS(FEC_2025!$M:$M,FEC_2025!$P:$P,"RESULTAT_FIN",FEC_2025!$N:$N,U$4) | ... Y18: =-SUMIFS(FEC_2025!$M:$M,FEC_2025!$P:$P,"RESULTAT_FIN",FEC_2025!$N:$N,Y$4)
A19: Résultat courant avant impôt | B19: =B17+B18 | C19: =C17+C18 | D19: =D17+D18 | E19: =E17+E18 | F19: =F17+F18 | G19: =G17+G18 | H19: =H17+H18 | I19: =I17+I18 | ... Y19: =Y17+Y18
A20: Résultat exceptionnel | B20: =-SUMIFS(FEC_2024!$M:$M,FEC_2024!$P:$P,"EXCEPTIONNEL",FEC_2024!$N:$N,B$4) | C20: =-SUMIFS(FEC_2024!$M:$M,FEC_2024!$P:$P,"EXCEPTIONNEL",FEC_2024!$N:$N,C$4) | D20: =-SUMIFS(FEC_2024!$M:$M,FEC_2024!$P:$P,"EXCEPTIONNEL",FEC_2024!$N:$N,D$4) | E20: =-SUMIFS(FEC_2024!$M:$M,FEC_2024!$P:$P,"EXCEPTIONNEL",FEC_2024!$N:$N,E$4) | F20: =-SUMIFS(FEC_2024!$M:$M,FEC_2024!$P:$P,"EXCEPTIONNEL",FEC_2024!$N:$N,F$4) | G20: =-SUMIFS(FEC_2024!$M:$M,FEC_2024!$P:$P,"EXCEPTIONNEL",FEC_2024!$N:$N,G$4) | H20: =-SUMIFS(FEC_2024!$M:$M,FEC_2024!$P:$P,"EXCEPTIONNEL",FEC_2024!$N:$N,H$4) | I20: =-SUMIFS(FEC_2024!$M:$M,FEC_2024!$P:$P,"EXCEPTIONNEL",FEC_2024!$N:$N,I$4) | ... M20: =-SUMIFS(FEC_2024!$M:$M,FEC_2024!$P:$P,"EXCEPTIONNEL",FEC_2024!$N:$N,M$4) | N20: =-SUMIFS(FEC_2025!$M:$M,FEC_2025!$P:$P,"EXCEPTIONNEL",FEC_2025!$N:$N,N$4) | O20: =-SUMIFS(FEC_2025!$M:$M,FEC_2025!$P:$P,"EXCEPTIONNEL",FEC_2025!$N:$N,O$4) | P20: =-SUMIFS(FEC_2025!$M:$M,FEC_2025!$P:$P,"EXCEPTIONNEL",FEC_2025!$N:$N,P$4) | Q20: =-SUMIFS(FEC_2025!$M:$M,FEC_2025!$P:$P,"EXCEPTIONNEL",FEC_2025!$N:$N,Q$4) | R20: =-SUMIFS(FEC_2025!$M:$M,FEC_2025!$P:$P,"EXCEPTIONNEL",FEC_2025!$N:$N,R$4) | S20: =-SUMIFS(FEC_2025!$M:$M,FEC_2025!$P:$P,"EXCEPTIONNEL",FEC_2025!$N:$N,S$4) | T20: =-SUMIFS(FEC_2025!$M:$M,FEC_2025!$P:$P,"EXCEPTIONNEL",FEC_2025!$N:$N,T$4) | U20: =-SUMIFS(FEC_2025!$M:$M,FEC_2025!$P:$P,"EXCEPTIONNEL",FEC_2025!$N:$N,U$4) | ... Y20: =-SUMIFS(FEC_2025!$M:$M,FEC_2025!$P:$P,"EXCEPTIONNEL",FEC_2025!$N:$N,Y$4)
A21: Participation des salariés | B21: =-SUMIFS(FEC_2024!$M:$M,FEC_2024!$P:$P,"PARTICIPATION",FEC_2024!$N:$N,B$4) | C21: =-SUMIFS(FEC_2024!$M:$M,FEC_2024!$P:$P,"PARTICIPATION",FEC_2024!$N:$N,C$4) | D21: =-SUMIFS(FEC_2024!$M:$M,FEC_2024!$P:$P,"PARTICIPATION",FEC_2024!$N:$N,D$4) | E21: =-SUMIFS(FEC_2024!$M:$M,FEC_2024!$P:$P,"PARTICIPATION",FEC_2024!$N:$N,E$4) | F21: =-SUMIFS(FEC_2024!$M:$M,FEC_2024!$P:$P,"PARTICIPATION",FEC_2024!$N:$N,F$4) | G21: =-SUMIFS(FEC_2024!$M:$M,FEC_2024!$P:$P,"PARTICIPATION",FEC_2024!$N:$N,G$4) | H21: =-SUMIFS(FEC_2024!$M:$M,FEC_2024!$P:$P,"PARTICIPATION",FEC_2024!$N:$N,H$4) | I21: =-SUMIFS(FEC_2024!$M:$M,FEC_2024!$P:$P,"PARTICIPATION",FEC_2024!$N:$N,I$4) | ... M21: =-SUMIFS(FEC_2024!$M:$M,FEC_2024!$P:$P,"PARTICIPATION",FEC_2024!$N:$N,M$4) | N21: =-SUMIFS(FEC_2025!$M:$M,FEC_2025!$P:$P,"PARTICIPATION",FEC_2025!$N:$N,N$4) | O21: =-SUMIFS(FEC_2025!$M:$M,FEC_2025!$P:$P,"PARTICIPATION",FEC_2025!$N:$N,O$4) | P21: =-SUMIFS(FEC_2025!$M:$M,FEC_2025!$P:$P,"PARTICIPATION",FEC_2025!$N:$N,P$4) | Q21: =-SUMIFS(FEC_2025!$M:$M,FEC_2025!$P:$P,"PARTICIPATION",FEC_2025!$N:$N,Q$4) | R21: =-SUMIFS(FEC_2025!$M:$M,FEC_2025!$P:$P,"PARTICIPATION",FEC_2025!$N:$N,R$4) | S21: =-SUMIFS(FEC_2025!$M:$M,FEC_2025!$P:$P,"PARTICIPATION",FEC_2025!$N:$N,S$4) | T21: =-SUMIFS(FEC_2025!$M:$M,FEC_2025!$P:$P,"PARTICIPATION",FEC_2025!$N:$N,T$4) | U21: =-SUMIFS(FEC_2025!$M:$M,FEC_2025!$P:$P,"PARTICIPATION",FEC_2025!$N:$N,U$4) | ... Y21: =-SUMIFS(FEC_2025!$M:$M,FEC_2025!$P:$P,"PARTICIPATION",FEC_2025!$N:$N,Y$4)
A22: Impôt sur les sociétés | B22: =-SUMIFS(FEC_2024!$M:$M,FEC_2024!$P:$P,"IS",FEC_2024!$N:$N,B$4) | C22: =-SUMIFS(FEC_2024!$M:$M,FEC_2024!$P:$P,"IS",FEC_2024!$N:$N,C$4) | D22: =-SUMIFS(FEC_2024!$M:$M,FEC_2024!$P:$P,"IS",FEC_2024!$N:$N,D$4) | E22: =-SUMIFS(FEC_2024!$M:$M,FEC_2024!$P:$P,"IS",FEC_2024!$N:$N,E$4) | F22: =-SUMIFS(FEC_2024!$M:$M,FEC_2024!$P:$P,"IS",FEC_2024!$N:$N,F$4) | G22: =-SUMIFS(FEC_2024!$M:$M,FEC_2024!$P:$P,"IS",FEC_2024!$N:$N,G$4) | H22: =-SUMIFS(FEC_2024!$M:$M,FEC_2024!$P:$P,"IS",FEC_2024!$N:$N,H$4) | I22: =-SUMIFS(FEC_2024!$M:$M,FEC_2024!$P:$P,"IS",FEC_2024!$N:$N,I$4) | ... M22: =-SUMIFS(FEC_2024!$M:$M,FEC_2024!$P:$P,"IS",FEC_2024!$N:$N,M$4) | N22: =-SUMIFS(FEC_2025!$M:$M,FEC_2025!$P:$P,"IS",FEC_2025!$N:$N,N$4) | O22: =-SUMIFS(FEC_2025!$M:$M,FEC_2025!$P:$P,"IS",FEC_2025!$N:$N,O$4) | P22: =-SUMIFS(FEC_2025!$M:$M,FEC_2025!$P:$P,"IS",FEC_2025!$N:$N,P$4) | Q22: =-SUMIFS(FEC_2025!$M:$M,FEC_2025!$P:$P,"IS",FEC_2025!$N:$N,Q$4) | R22: =-SUMIFS(FEC_2025!$M:$M,FEC_2025!$P:$P,"IS",FEC_2025!$N:$N,R$4) | S22: =-SUMIFS(FEC_2025!$M:$M,FEC_2025!$P:$P,"IS",FEC_2025!$N:$N,S$4) | T22: =-SUMIFS(FEC_2025!$M:$M,FEC_2025!$P:$P,"IS",FEC_2025!$N:$N,T$4) | U22: =-SUMIFS(FEC_2025!$M:$M,FEC_2025!$P:$P,"IS",FEC_2025!$N:$N,U$4) | ... Y22: =-SUMIFS(FEC_2025!$M:$M,FEC_2025!$P:$P,"IS",FEC_2025!$N:$N,Y$4)
A23: Résultat net | B23: =B19+B20+B21+B22 | C23: =C19+C20+C21+C22 | D23: =D19+D20+D21+D22 | E23: =E19+E20+E21+E22 | F23: =F19+F20+F21+F22 | G23: =G19+G20+G21+G22 | H23: =H19+H20+H21+H22 | I23: =I19+I20+I21+I22 | ... Y23: =Y19+Y20+Y21+Y22
A25: Écritures de clôture incluses dans le résultat
A26: dont écritures d'inventaire (type INVENTAIRE) | B26: =-SUMIFS(FEC_2024!$M:$M,FEC_2024!$O:$O,"INVENTAIRE",FEC_2024!$N:$N,B$4,FEC_2024!$Q:$Q,"6")-SUMIFS(FEC_2024!$M:$M,FEC_2024!$O:$O,"INVENTAIRE",FEC_2024!$N:$N,B$4,FEC_2024!$Q:$Q,"7") | C26: =-SUMIFS(FEC_2024!$M:$M,FEC_2024!$O:$O,"INVENTAIRE",FEC_2024!$N:$N,C$4,FEC_2024!$Q:$Q,"6")-SUMIFS(FEC_2024!$M:$M,FEC_2024!$O:$O,"INVENTAIRE",FEC_2024!$N:$N,C$4,FEC_2024!$Q:$Q,"7") | D26: =-SUMIFS(FEC_2024!$M:$M,FEC_2024!$O:$O,"INVENTAIRE",FEC_2024!$N:$N,D$4,FEC_2024!$Q:$Q,"6")-SUMIFS(FEC_2024!$M:$M,FEC_2024!$O:$O,"INVENTAIRE",FEC_2024!$N:$N,D$4,FEC_2024!$Q:$Q,"7") | E26: =-SUMIFS(FEC_2024!$M:$M,FEC_2024!$O:$O,"INVENTAIRE",FEC_2024!$N:$N,E$4,FEC_2024!$Q:$Q,"6")-SUMIFS(FEC_2024!$M:$M,FEC_2024!$O:$O,"INVENTAIRE",FEC_2024!$N:$N,E$4,FEC_2024!$Q:$Q,"7") | F26: =-SUMIFS(FEC_2024!$M:$M,FEC_2024!$O:$O,"INVENTAIRE",FEC_2024!$N:$N,F$4,FEC_2024!$Q:$Q,"6")-SUMIFS(FEC_2024!$M:$M,FEC_2024!$O:$O,"INVENTAIRE",FEC_2024!$N:$N,F$4,FEC_2024!$Q:$Q,"7") | G26: =-SUMIFS(FEC_2024!$M:$M,FEC_2024!$O:$O,"INVENTAIRE",FEC_2024!$N:$N,G$4,FEC_2024!$Q:$Q,"6")-SUMIFS(FEC_2024!$M:$M,FEC_2024!$O:$O,"INVENTAIRE",FEC_2024!$N:$N,G$4,FEC_2024!$Q:$Q,"7") | H26: =-SUMIFS(FEC_2024!$M:$M,FEC_2024!$O:$O,"INVENTAIRE",FEC_2024!$N:$N,H$4,FEC_2024!$Q:$Q,"6")-SUMIFS(FEC_2024!$M:$M,FEC_2024!$O:$O,"INVENTAIRE",FEC_2024!$N:$N,H$4,FEC_2024!$Q:$Q,"7") | I26: =-SUMIFS(FEC_2024!$M:$M,FEC_2024!$O:$O,"INVENTAIRE",FEC_2024!$N:$N,I$4,FEC_2024!$Q:$Q,"6")-SUMIFS(FEC_2024!$M:$M,FEC_2024!$O:$O,"INVENTAIRE",FEC_2024!$N:$N,I$4,FEC_2024!$Q:$Q,"7") | ... M26: =-SUMIFS(FEC_2024!$M:$M,FEC_2024!$O:$O,"INVENTAIRE",FEC_2024!$N:$N,M$4,FEC_2024!$Q:$Q,"6")-SUMIFS(FEC_2024!$M:$M,FEC_2024!$O:$O,"INVENTAIRE",FEC_2024!$N:$N,M$4,FEC_2024!$Q:$Q,"7") | N26: =-SUMIFS(FEC_2025!$M:$M,FEC_2025!$O:$O,"INVENTAIRE",FEC_2025!$N:$N,N$4,FEC_2025!$Q:$Q,"6")-SUMIFS(FEC_2025!$M:$M,FEC_2025!$O:$O,"INVENTAIRE",FEC_2025!$N:$N,N$4,FEC_2025!$Q:$Q,"7") | O26: =-SUMIFS(FEC_2025!$M:$M,FEC_2025!$O:$O,"INVENTAIRE",FEC_2025!$N:$N,O$4,FEC_2025!$Q:$Q,"6")-SUMIFS(FEC_2025!$M:$M,FEC_2025!$O:$O,"INVENTAIRE",FEC_2025!$N:$N,O$4,FEC_2025!$Q:$Q,"7") | P26: =-SUMIFS(FEC_2025!$M:$M,FEC_2025!$O:$O,"INVENTAIRE",FEC_2025!$N:$N,P$4,FEC_2025!$Q:$Q,"6")-SUMIFS(FEC_2025!$M:$M,FEC_2025!$O:$O,"INVENTAIRE",FEC_2025!$N:$N,P$4,FEC_2025!$Q:$Q,"7") | Q26: =-SUMIFS(FEC_2025!$M:$M,FEC_2025!$O:$O,"INVENTAIRE",FEC_2025!$N:$N,Q$4,FEC_2025!$Q:$Q,"6")-SUMIFS(FEC_2025!$M:$M,FEC_2025!$O:$O,"INVENTAIRE",FEC_2025!$N:$N,Q$4,FEC_2025!$Q:$Q,"7") | R26: =-SUMIFS(FEC_2025!$M:$M,FEC_2025!$O:$O,"INVENTAIRE",FEC_2025!$N:$N,R$4,FEC_2025!$Q:$Q,"6")-SUMIFS(FEC_2025!$M:$M,FEC_2025!$O:$O,"INVENTAIRE",FEC_2025!$N:$N,R$4,FEC_2025!$Q:$Q,"7") | S26: =-SUMIFS(FEC_2025!$M:$M,FEC_2025!$O:$O,"INVENTAIRE",FEC_2025!$N:$N,S$4,FEC_2025!$Q:$Q,"6")-SUMIFS(FEC_2025!$M:$M,FEC_2025!$O:$O,"INVENTAIRE",FEC_2025!$N:$N,S$4,FEC_2025!$Q:$Q,"7") | T26: =-SUMIFS(FEC_2025!$M:$M,FEC_2025!$O:$O,"INVENTAIRE",FEC_2025!$N:$N,T$4,FEC_2025!$Q:$Q,"6")-SUMIFS(FEC_2025!$M:$M,FEC_2025!$O:$O,"INVENTAIRE",FEC_2025!$N:$N,T$4,FEC_2025!$Q:$Q,"7") | U26: =-SUMIFS(FEC_2025!$M:$M,FEC_2025!$O:$O,"INVENTAIRE",FEC_2025!$N:$N,U$4,FEC_2025!$Q:$Q,"6")-SUMIFS(FEC_2025!$M:$M,FEC_2025!$O:$O,"INVENTAIRE",FEC_2025!$N:$N,U$4,FEC_2025!$Q:$Q,"7") | ... Y26: =-SUMIFS(FEC_2025!$M:$M,FEC_2025!$O:$O,"INVENTAIRE",FEC_2025!$N:$N,Y$4,FEC_2025!$Q:$Q,"6")-SUMIFS(FEC_2025!$M:$M,FEC_2025!$O:$O,"INVENTAIRE",FEC_2025!$N:$N,Y$4,FEC_2025!$Q:$Q,"7")
A27: dont extournes d'ouverture (type EXTOURNE) | B27: =-SUMIFS(FEC_2024!$M:$M,FEC_2024!$O:$O,"EXTOURNE",FEC_2024!$N:$N,B$4,FEC_2024!$Q:$Q,"6")-SUMIFS(FEC_2024!$M:$M,FEC_2024!$O:$O,"EXTOURNE",FEC_2024!$N:$N,B$4,FEC_2024!$Q:$Q,"7") | C27: =-SUMIFS(FEC_2024!$M:$M,FEC_2024!$O:$O,"EXTOURNE",FEC_2024!$N:$N,C$4,FEC_2024!$Q:$Q,"6")-SUMIFS(FEC_2024!$M:$M,FEC_2024!$O:$O,"EXTOURNE",FEC_2024!$N:$N,C$4,FEC_2024!$Q:$Q,"7") | D27: =-SUMIFS(FEC_2024!$M:$M,FEC_2024!$O:$O,"EXTOURNE",FEC_2024!$N:$N,D$4,FEC_2024!$Q:$Q,"6")-SUMIFS(FEC_2024!$M:$M,FEC_2024!$O:$O,"EXTOURNE",FEC_2024!$N:$N,D$4,FEC_2024!$Q:$Q,"7") | E27: =-SUMIFS(FEC_2024!$M:$M,FEC_2024!$O:$O,"EXTOURNE",FEC_2024!$N:$N,E$4,FEC_2024!$Q:$Q,"6")-SUMIFS(FEC_2024!$M:$M,FEC_2024!$O:$O,"EXTOURNE",FEC_2024!$N:$N,E$4,FEC_2024!$Q:$Q,"7") | F27: =-SUMIFS(FEC_2024!$M:$M,FEC_2024!$O:$O,"EXTOURNE",FEC_2024!$N:$N,F$4,FEC_2024!$Q:$Q,"6")-SUMIFS(FEC_2024!$M:$M,FEC_2024!$O:$O,"EXTOURNE",FEC_2024!$N:$N,F$4,FEC_2024!$Q:$Q,"7") | G27: =-SUMIFS(FEC_2024!$M:$M,FEC_2024!$O:$O,"EXTOURNE",FEC_2024!$N:$N,G$4,FEC_2024!$Q:$Q,"6")-SUMIFS(FEC_2024!$M:$M,FEC_2024!$O:$O,"EXTOURNE",FEC_2024!$N:$N,G$4,FEC_2024!$Q:$Q,"7") | H27: =-SUMIFS(FEC_2024!$M:$M,FEC_2024!$O:$O,"EXTOURNE",FEC_2024!$N:$N,H$4,FEC_2024!$Q:$Q,"6")-SUMIFS(FEC_2024!$M:$M,FEC_2024!$O:$O,"EXTOURNE",FEC_2024!$N:$N,H$4,FEC_2024!$Q:$Q,"7") | I27: =-SUMIFS(FEC_2024!$M:$M,FEC_2024!$O:$O,"EXTOURNE",FEC_2024!$N:$N,I$4,FEC_2024!$Q:$Q,"6")-SUMIFS(FEC_2024!$M:$M,FEC_2024!$O:$O,"EXTOURNE",FEC_2024!$N:$N,I$4,FEC_2024!$Q:$Q,"7") | ... M27: =-SUMIFS(FEC_2024!$M:$M,FEC_2024!$O:$O,"EXTOURNE",FEC_2024!$N:$N,M$4,FEC_2024!$Q:$Q,"6")-SUMIFS(FEC_2024!$M:$M,FEC_2024!$O:$O,"EXTOURNE",FEC_2024!$N:$N,M$4,FEC_2024!$Q:$Q,"7") | N27: =-SUMIFS(FEC_2025!$M:$M,FEC_2025!$O:$O,"EXTOURNE",FEC_2025!$N:$N,N$4,FEC_2025!$Q:$Q,"6")-SUMIFS(FEC_2025!$M:$M,FEC_2025!$O:$O,"EXTOURNE",FEC_2025!$N:$N,N$4,FEC_2025!$Q:$Q,"7") | O27: =-SUMIFS(FEC_2025!$M:$M,FEC_2025!$O:$O,"EXTOURNE",FEC_2025!$N:$N,O$4,FEC_2025!$Q:$Q,"6")-SUMIFS(FEC_2025!$M:$M,FEC_2025!$O:$O,"EXTOURNE",FEC_2025!$N:$N,O$4,FEC_2025!$Q:$Q,"7") | P27: =-SUMIFS(FEC_2025!$M:$M,FEC_2025!$O:$O,"EXTOURNE",FEC_2025!$N:$N,P$4,FEC_2025!$Q:$Q,"6")-SUMIFS(FEC_2025!$M:$M,FEC_2025!$O:$O,"EXTOURNE",FEC_2025!$N:$N,P$4,FEC_2025!$Q:$Q,"7") | Q27: =-SUMIFS(FEC_2025!$M:$M,FEC_2025!$O:$O,"EXTOURNE",FEC_2025!$N:$N,Q$4,FEC_2025!$Q:$Q,"6")-SUMIFS(FEC_2025!$M:$M,FEC_2025!$O:$O,"EXTOURNE",FEC_2025!$N:$N,Q$4,FEC_2025!$Q:$Q,"7") | R27: =-SUMIFS(FEC_2025!$M:$M,FEC_2025!$O:$O,"EXTOURNE",FEC_2025!$N:$N,R$4,FEC_2025!$Q:$Q,"6")-SUMIFS(FEC_2025!$M:$M,FEC_2025!$O:$O,"EXTOURNE",FEC_2025!$N:$N,R$4,FEC_2025!$Q:$Q,"7") | S27: =-SUMIFS(FEC_2025!$M:$M,FEC_2025!$O:$O,"EXTOURNE",FEC_2025!$N:$N,S$4,FEC_2025!$Q:$Q,"6")-SUMIFS(FEC_2025!$M:$M,FEC_2025!$O:$O,"EXTOURNE",FEC_2025!$N:$N,S$4,FEC_2025!$Q:$Q,"7") | T27: =-SUMIFS(FEC_2025!$M:$M,FEC_2025!$O:$O,"EXTOURNE",FEC_2025!$N:$N,T$4,FEC_2025!$Q:$Q,"6")-SUMIFS(FEC_2025!$M:$M,FEC_2025!$O:$O,"EXTOURNE",FEC_2025!$N:$N,T$4,FEC_2025!$Q:$Q,"7") | U27: =-SUMIFS(FEC_2025!$M:$M,FEC_2025!$O:$O,"EXTOURNE",FEC_2025!$N:$N,U$4,FEC_2025!$Q:$Q,"6")-SUMIFS(FEC_2025!$M:$M,FEC_2025!$O:$O,"EXTOURNE",FEC_2025!$N:$N,U$4,FEC_2025!$Q:$Q,"7") | ... Y27: =-SUMIFS(FEC_2025!$M:$M,FEC_2025!$O:$O,"EXTOURNE",FEC_2025!$N:$N,Y$4,FEC_2025!$Q:$Q,"6")-SUMIFS(FEC_2025!$M:$M,FEC_2025!$O:$O,"EXTOURNE",FEC_2025!$N:$N,Y$4,FEC_2025!$Q:$Q,"7")
A28: Résultat mensuel hors écritures de clôture | B28: =B23-B26-B27 | C28: =C23-C26-C27 | D28: =D23-D26-D27 | E28: =E23-E26-E27 | F28: =F23-F26-F27 | G28: =G23-G26-G27 | H28: =H23-H26-H27 | I28: =I23-I26-I27 | ... Y28: =Y23-Y26-Y27
A29: EBITDA mensuel hors écritures de clôture (approximation : clôture imputée en totalité à l'EBITDA) | B29: =B15-B26-B27 | C29: =C15-C26-C27 | D29: =D15-D26-D27 | E29: =E15-E26-E27 | F29: =F15-F26-F27 | G29: =G15-G26-G27 | H29: =H15-H26-H27 | I29: =I15-I26-I27 | ... Y29: =Y15-Y26-Y27

Sheet Bilan_synth
A1: Bilan économique
A2: En euros. Fournisseurs et trésorerie présentés en négatif ; dette nette positive = endettement net.
A4: Poste | B4: 2024 (31/12/2024) | C4: 2025 (31/12/2025)
A5: Immobilisations incorporelles brutes | B5: =SUMIFS(Comptes!$F$5:$F$42,Comptes!$H$5:$H$42,"IMMO_INCORP") | C5: =SUMIFS(Comptes!$I$5:$I$42,Comptes!$K$5:$K$42,"IMMO_INCORP")
A6: Immobilisations corporelles brutes | B6: =SUMIFS(Comptes!$F$5:$F$42,Comptes!$H$5:$H$42,"IMMO_CORP") | C6: =SUMIFS(Comptes!$I$5:$I$42,Comptes!$K$5:$K$42,"IMMO_CORP")
A7: Immobilisations financières | B7: =SUMIFS(Comptes!$F$5:$F$42,Comptes!$H$5:$H$42,"IMMO_FIN") | C7: =SUMIFS(Comptes!$I$5:$I$42,Comptes!$K$5:$K$42,"IMMO_FIN")
A8: Amortissements et dépréciations | B8: =SUMIFS(Comptes!$F$5:$F$42,Comptes!$H$5:$H$42,"AMORT_DEPREC") | C8: =SUMIFS(Comptes!$I$5:$I$42,Comptes!$K$5:$K$42,"AMORT_DEPREC")
A9: ACTIF IMMOBILISÉ NET | B9: =B5+B6+B7+B8 | C9: =C5+C6+C7+C8
A10: Stocks et en-cours | B10: =SUMIFS(Comptes!$F$5:$F$42,Comptes!$H$5:$H$42,"STOCKS") | C10: =SUMIFS(Comptes!$I$5:$I$42,Comptes!$K$5:$K$42,"STOCKS")
A11: Clients nets | B11: =SUMIFS(Comptes!$F$5:$F$42,Comptes!$H$5:$H$42,"CLIENTS") | C11: =SUMIFS(Comptes!$I$5:$I$42,Comptes!$K$5:$K$42,"CLIENTS")
A12: Fournisseurs | B12: =SUMIFS(Comptes!$F$5:$F$42,Comptes!$H$5:$H$42,"FOURNISSEURS") | C12: =SUMIFS(Comptes!$I$5:$I$42,Comptes!$K$5:$K$42,"FOURNISSEURS")
A13: BFR d'exploitation | B13: =B10+B11+B12 | C13: =C10+C11+C12
A14: Dettes fiscales nettes (TVA, IS, CFE) | B14: =SUMIFS(Comptes!$F$5:$F$42,Comptes!$H$5:$H$42,"DETTES_FISCALES") | C14: =SUMIFS(Comptes!$I$5:$I$42,Comptes!$K$5:$K$42,"DETTES_FISCALES")
A15: Dettes sociales | B15: =SUMIFS(Comptes!$F$5:$F$42,Comptes!$H$5:$H$42,"DETTES_SOCIALES") | C15: =SUMIFS(Comptes!$I$5:$I$42,Comptes!$K$5:$K$42,"DETTES_SOCIALES")
A16: Autres créances | B16: =SUMIFS(Comptes!$F$5:$F$42,Comptes!$H$5:$H$42,"AUTRES_CREANCES") | C16: =SUMIFS(Comptes!$I$5:$I$42,Comptes!$K$5:$K$42,"AUTRES_CREANCES")
A17: Autres dettes | B17: =SUMIFS(Comptes!$F$5:$F$42,Comptes!$H$5:$H$42,"AUTRES_DETTES") | C17: =SUMIFS(Comptes!$I$5:$I$42,Comptes!$K$5:$K$42,"AUTRES_DETTES")
A18: Charges et produits constatés d'avance | B18: =SUMIFS(Comptes!$F$5:$F$42,Comptes!$H$5:$H$42,"CCA_PCA") | C18: =SUMIFS(Comptes!$I$5:$I$42,Comptes!$K$5:$K$42,"CCA_PCA")
A19: BFR hors exploitation | B19: =B14+B15+B16+B17+B18 | C19: =C14+C15+C16+C17+C18
A20: BFR TOTAL | B20: =B13+B19 | C20: =C13+C19
A21: ACTIF ÉCONOMIQUE | B21: =B9+B20 | C21: =C9+C20
A22: Trésorerie active | B22: =-SUMIFS(Comptes!$F$5:$F$42,Comptes!$H$5:$H$42,"TRESORERIE") | C22: =-SUMIFS(Comptes!$I$5:$I$42,Comptes!$K$5:$K$42,"TRESORERIE")
A23: Compte courant factor (solde débiteur = disponible) | B23: =-SUMIFS(Comptes!$F$5:$F$42,Comptes!$H$5:$H$42,"FACTOR_CC") | C23: =-SUMIFS(Comptes!$I$5:$I$42,Comptes!$K$5:$K$42,"FACTOR_CC")
A24: Concours bancaires courants | B24: =-SUMIFS(Comptes!$F$5:$F$42,Comptes!$H$5:$H$42,"CONCOURS_BANCAIRES") | C24: =-SUMIFS(Comptes!$I$5:$I$42,Comptes!$K$5:$K$42,"CONCOURS_BANCAIRES")
A25: Emprunts (y c. intérêts courus) | B25: =-SUMIFS(Comptes!$F$5:$F$42,Comptes!$H$5:$H$42,"EMPRUNTS") | C25: =-SUMIFS(Comptes!$I$5:$I$42,Comptes!$K$5:$K$42,"EMPRUNTS")
A26: Comptes courants d'associés | B26: =-SUMIFS(Comptes!$F$5:$F$42,Comptes!$H$5:$H$42,"COMPTES_COURANTS") | C26: =-SUMIFS(Comptes!$I$5:$I$42,Comptes!$K$5:$K$42,"COMPTES_COURANTS")
A27: DETTE NETTE (y c. comptes courants) | B27: =B22+B23+B24+B25+B26 | C27: =C22+C23+C24+C25+C26
A28: Capitaux propres hors résultat | B28: =-SUMIFS(Comptes!$F$5:$F$42,Comptes!$H$5:$H$42,"CAPITAUX_PROPRES") | C28: =-SUMIFS(Comptes!$I$5:$I$42,Comptes!$K$5:$K$42,"CAPITAUX_PROPRES")
A29: Résultat de l'exercice | B29: =-SUMIFS(Comptes!$F$5:$F$42,Comptes!$A$5:$A$42,"6*")-SUMIFS(Comptes!$F$5:$F$42,Comptes!$A$5:$A$42,"7*") | C29: =-SUMIFS(Comptes!$I$5:$I$42,Comptes!$A$5:$A$42,"6*")-SUMIFS(Comptes!$I$5:$I$42,Comptes!$A$5:$A$42,"7*")
A30: Provisions pour risques et charges | B30: =-SUMIFS(Comptes!$F$5:$F$42,Comptes!$H$5:$H$42,"PROVISIONS") | C30: =-SUMIFS(Comptes!$I$5:$I$42,Comptes!$K$5:$K$42,"PROVISIONS")
A31: CAPITAUX PROPRES ET PROVISIONS | B31: =B28+B29+B30 | C31: =C28+C29+C30
A32: Contrôle : actif économique - dette nette - capitaux propres | B32: =B21-B27-B31 | C32: =C21-C27-C31
A34: Ratios de rotation
A35: Taux de TVA moyen appliqué au CA et aux achats (hypothèse, modifiable) | B35: 0.2
A36: Nombre de jours de la période | B36: 366 | C36: 365
A37: DSO (clients nets TTC / CA TTC) | B37: =IF(PnL_annuel!B5=0,0,B11/(PnL_annuel!B5*(1+$B$35))*B$36) | C37: =IF(PnL_annuel!D5=0,0,C11/(PnL_annuel!D5*(1+$B$35))*C$36)
A38: DPO (fournisseurs TTC / coûts directs et charges externes TTC) | B38: =IF((PnL_annuel!B9+PnL_annuel!B11)=0,0,B12/((PnL_annuel!B9+PnL_annuel!B11)*(1+$B$35))*B$36) | C38: =IF((PnL_annuel!D9+PnL_annuel!D11)=0,0,C12/((PnL_annuel!D9+PnL_annuel!D11)*(1+$B$35))*C$36)
A39: BFR d'exploitation en jours de CA HT | B39: =IF(PnL_annuel!B5=0,0,B13/PnL_annuel!B5*B$36) | C39: =IF(PnL_annuel!D5=0,0,C13/PnL_annuel!D5*C$36)
A40: Dette nette / EBITDA (annualisé si période partielle) | B40: =IF(PnL_annuel!B15<=0,"n.s.",B27/(PnL_annuel!B15*365/B$36)) | C40: =IF(PnL_annuel!D15<=0,"n.s.",C27/(PnL_annuel!D15*365/C$36))

Sheet Tresorerie
A1: Trésorerie comptable fin de mois
A2: Soldes des comptes 51 et 53 (hors intérêts courus 518) à chaque fin de mois, à-nouveaux inclus. Positif = disponible.
C3: 45322 | D3: 45351 | E3: 45382 | F3: 45412 | G3: 45443 | H3: 45473 | I3: 45504 | J3: 45535 | K3: 45565 | L3: 45596 | M3: 45626 | N3: 45657 | O3: 45688 | P3: 45716 | Q3: 45747 | R3: 45777 | S3: 45808 | T3: 45838 | U3: 45869 | V3: 45900 | W3: 45930 | X3: 45961 | Y3: 45991 | Z3: 46022
A4: Compte | B4: Libellé | C4: 2024-01 | D4: 2024-02 | E4: 2024-03 | F4: 2024-04 | G4: 2024-05 | H4: 2024-06 | I4: 2024-07 | J4: 2024-08 | K4: 2024-09 | L4: 2024-10 | M4: 2024-11 | N4: 2024-12 | O4: 2025-01 | P4: 2025-02 | Q4: 2025-03 | R4: 2025-04 | S4: 2025-05 | T4: 2025-06 | U4: 2025-07 | V4: 2025-08 | W4: 2025-09 | X4: 2025-10 | Y4: 2025-11 | Z4: 2025-12
A5: 512000 | B5: Banque Fictive | C5: =SUMIFS(FEC_2024!$M:$M,FEC_2024!$E:$E,$A5,FEC_2024!$D:$D,"<="&C$3) | D5: =SUMIFS(FEC_2024!$M:$M,FEC_2024!$E:$E,$A5,FEC_2024!$D:$D,"<="&D$3) | E5: =SUMIFS(FEC_2024!$M:$M,FEC_2024!$E:$E,$A5,FEC_2024!$D:$D,"<="&E$3) | F5: =SUMIFS(FEC_2024!$M:$M,FEC_2024!$E:$E,$A5,FEC_2024!$D:$D,"<="&F$3) | G5: =SUMIFS(FEC_2024!$M:$M,FEC_2024!$E:$E,$A5,FEC_2024!$D:$D,"<="&G$3) | H5: =SUMIFS(FEC_2024!$M:$M,FEC_2024!$E:$E,$A5,FEC_2024!$D:$D,"<="&H$3) | I5: =SUMIFS(FEC_2024!$M:$M,FEC_2024!$E:$E,$A5,FEC_2024!$D:$D,"<="&I$3) | J5: =SUMIFS(FEC_2024!$M:$M,FEC_2024!$E:$E,$A5,FEC_2024!$D:$D,"<="&J$3) | ... N5: =SUMIFS(FEC_2024!$M:$M,FEC_2024!$E:$E,$A5,FEC_2024!$D:$D,"<="&N$3) | O5: =SUMIFS(FEC_2025!$M:$M,FEC_2025!$E:$E,$A5,FEC_2025!$D:$D,"<="&O$3) | P5: =SUMIFS(FEC_2025!$M:$M,FEC_2025!$E:$E,$A5,FEC_2025!$D:$D,"<="&P$3) | Q5: =SUMIFS(FEC_2025!$M:$M,FEC_2025!$E:$E,$A5,FEC_2025!$D:$D,"<="&Q$3) | R5: =SUMIFS(FEC_2025!$M:$M,FEC_2025!$E:$E,$A5,FEC_2025!$D:$D,"<="&R$3) | S5: =SUMIFS(FEC_2025!$M:$M,FEC_2025!$E:$E,$A5,FEC_2025!$D:$D,"<="&S$3) | T5: =SUMIFS(FEC_2025!$M:$M,FEC_2025!$E:$E,$A5,FEC_2025!$D:$D,"<="&T$3) | U5: =SUMIFS(FEC_2025!$M:$M,FEC_2025!$E:$E,$A5,FEC_2025!$D:$D,"<="&U$3) | V5: =SUMIFS(FEC_2025!$M:$M,FEC_2025!$E:$E,$A5,FEC_2025!$D:$D,"<="&V$3) | ... Z5: =SUMIFS(FEC_2025!$M:$M,FEC_2025!$E:$E,$A5,FEC_2025!$D:$D,"<="&Z$3)
A6: TOTAL TRÉSORERIE | C6: =SUM(C5:C5) | D6: =SUM(D5:D5) | E6: =SUM(E5:E5) | F6: =SUM(F5:F5) | G6: =SUM(G5:G5) | H6: =SUM(H5:H5) | I6: =SUM(I5:I5) | J6: =SUM(J5:J5) | ... Z6: =SUM(Z5:Z5)
A8: Point bas par exercice
A9: 2024 | C9: =MIN(C6:N6)
A10: 2025 | C10: =MIN(O6:Z6)

Sheet Creances
A1: Créances clients : concentration, intragroupe, ancienneté, coupure
A2: Valeurs calculées par l'application (non recalculées dans Excel). Ancienneté : solde exact de chaque client imputé sur ses factures les plus récentes (FIFO), indépendamment du lettrage.
A4: Indicateur | B4: 2024 | C4: 2025 | D4: Lecture
A5: Chiffre d'affaires facturé HT (journaux de ventes) | B5: 1983333.3 | C5: 1520000
A6: dont sociétés du groupe | B6: 0 | C6: 0 | D6: Sociétés du groupe : aucune identifiée
A7: Part intragroupe du chiffre d'affaires | B7: 0 | C7: 0
A8: Nombre de clients facturés | B8: 8 | C8: 8
A9: Poids du 1er client hors groupe | B9: 0.1675185 | C9: 0.201038 | D9: Au-delà de 20 % : dépendance à documenter (contrat, solvabilité du client).
A10: Poids des 5 premiers clients hors groupe | B10: 0.75008603 | C10: 0.75015334
A11: Poids des 10 premiers clients hors groupe | B11: 1 | C11: 1
A12: Solde des comptes clients (411 à 417) | B12: 258238.9 | C12: 515457.32
A13: Encours clients hors groupe | B13: 258238.9 | C13: 515457.32
A14: dont plus de 90 jours | B14: 0 | C14: 48000
A15: dont plus de 180 jours | B15: 0 | C15: 25113.06 | D15: Créances anciennes non provisionnées : risque de surévaluation de l'actif.
A16: Encours sur les sociétés du groupe | B16: 0 | C16: 0 | D16: Recouvrabilité à apprécier au niveau du groupe (situation de la société débitrice).
A17: Clients créditeurs (trop-perçus, acomptes non imputés) | B17: 0 | C17: 0
A18: Créances douteuses (416) | B18: 0 | C18: 0
A19: Provisions pour dépréciation (491) | B19: 0 | C19: 0
A20: Factures à établir (418) | B20: 0 | C20: 0 | D20: Un montant identique d'un exercice à l'autre est anormal (produit ancien non facturé).
A21: DSO clients hors groupe (jours) | B21: 40 | C21: 103 | D21: Encours TTC hors groupe / CA TTC hors groupe × jours de la période.
A22: Lettrage : part du facturé lettrée | B22: 0.89149626 | C22: 0.71740278 | D22: Sous 70 % : les délais issus du lettrage sont peu fiables ; l'ancienneté FIFO ci-dessus n'en dépend pas.
A23: Facturation des 5 derniers jours (HT) | B23: 31815.11 | C23: 109914.24
A24: Moyenne de 5 jours sur l'exercice (HT) | B24: 27094.72 | C24: 20821.92
A25: Ratio fin d'exercice / moyenne | B25: 1.1742182 | C25: 5.2787761 | D25: Au-delà de 2 : vérifier la coupure (livraisons réellement faites avant la clôture).
A26: CA du dernier mois / moyenne des autres mois | B26: 0.95433782 | C26: 1.747141
A27: Avoirs émis dans les 31 jours suivant la clôture (HT) | B27: 0 | C27: n.d. | D27: Avoirs en début d'exercice suivant sur des ventes de fin d'exercice : chiffre d'affaires possiblement anticipé.
A28: Part des règlements clients passant par le factor | B28: 0 | C28: 0
A31: Top 20 clients — 2025 (chiffre d'affaires HT)
A32: Client | B32: CA HT | C32: % du total | D32: Groupe | E32: Factures
A33: Agence Mobilis | B33: 305577.75 | C33: 0.201038 | E33: 10
A34: Coworking Atelier 9 | B34: 274397.31 | C34: 0.18052455 | E34: 11
A35: Hotel Les Tilleuls | B35: 226628.29 | C35: 0.14909756 | E35: 10
A36: Boutique Hetre et Chene | B36: 181389.39 | C36: 0.11933513 | E36: 8
A37: Clinique du Parc | B37: 152240.31 | C37: 0.1001581 | E37: 6
A38: Cabinet Varenne Associes | B38: 145517.52 | C38: 0.095735212 | E38: 7
A39: Restaurant Le Comptoir | B39: 126872.8 | C39: 0.083468949 | E39: 4
A40: Residence Bel Air | B40: 107376.6 | C40: 0.070642501 | E40: 5
A43: Ancienneté des soldes clients — 2025 (au 31/12/2025), méthode FIFO
A44: Client | B44: Solde | C44: Groupe | D44: 0-30 j | E44: 31-60 j | F44: 61-90 j | G44: 91-180 j | H44: > 180 j
A45: Agence Mobilis | B45: 178027.53 | D45: 96000 | E45: 52195.22 | F45: 29832.31 | G45: 0 | H45: 0
...

Sheet Dettes_fournisseurs
A1: Dettes fournisseurs : concentration, intragroupe, ancienneté, factures non parvenues
A2: Valeurs calculées par l'application. Ancienneté : solde exact de chaque fournisseur imputé sur ses factures les plus récentes (FIFO), depuis la date de pièce.
A4: Indicateur | B4: 2024 | C4: 2025 | D4: Lecture
A5: Achats facturés HT (journaux d'achats) | B5: 1013184 | C5: 860910.51
A6: dont sociétés du groupe | B6: 0 | C6: 0 | D6: Sociétés du groupe : aucune identifiée
A7: Part intragroupe des achats | B7: 0 | C7: 0
A8: Nombre de fournisseurs | B8: 8 | C8: 8
A9: Poids du 1er fournisseur hors groupe | B9: 0.36517028 | C9: 0.38577445 | D9: Au-delà de 30 % : dépendance ; ce fournisseur est souvent le créancier qui décide du sort de l'entreprise.
A10: Poids des 5 premiers fournisseurs hors groupe | B10: 0.9587834 | C10: 0.95149322
A11: Poids des 10 premiers fournisseurs hors groupe | B11: 1 | C11: 1
A12: Dettes fournisseurs hors groupe (401 à 404) | B12: 153814.87 | C12: 202786.83
A13: dont factures de plus de 60 jours | B13: 0 | C13: 36776.26 | D13: Délai légal : 60 jours date de facture (45 jours fin de mois sur option), sauf accord particulier.
A14: dont plus de 90 jours | B14: 0 | C14: 15500
A15: dont plus d'un an | B15: 0 | C15: 0 | D15: Dettes anciennes : passif gelé (procédure, plan) ou litige ; à qualifier.
A16: Dettes envers les sociétés du groupe | B16: 0 | C16: 0
A17: dont effets à payer (403) | B17: 0 | C17: 0
A18: dont fournisseurs d'immobilisations (404) | B18: 0 | C18: 0
A19: Fournisseurs débiteurs (soldes débiteurs) | B19: 0 | C19: 0 | D19: Avoirs à recevoir, acomptes, doubles paiements : à justifier.
A20: Avances et acomptes versés (409) | B20: 0 | C20: 0
A21: Factures non parvenues (408) | B21: 0 | C21: 0
A22: Mouvements du compte 408 dans l'exercice (lignes) | B22: 0 | C22: 0 | D22: Aucun mouvement et solde identique : provision figée, sans rapport avec des factures attendues.
A23: 408 identique à l'exercice précédent | B23: n.d. | C23: non
A24: DPO hors groupe (jours) | B24: 46 | C24: 72 | D24: Dettes TTC hors groupe / achats TTC hors groupe × jours de la période.
A27: Top 20 fournisseurs — 2025 (achats HT)
A28: Fournisseur | B28: Achats HT | C28: % du total | D28: Groupe | E28: Factures
A29: Scierie du Nord | B29: 332117.28 | C29: 0.38577445 | E29: 16
A30: Quincaillerie Pro Est | B30: 192383.68 | C30: 0.22346536 | E30: 9
A31: Vernis et Finitions | B31: 157499.05 | C31: 0.18294474 | E31: 9
A32: SCI Les Halles | B32: 102000 | C32: 0.11847921 | E32: 12
A33: Energie Plus | B33: 35150.5 | C33: 0.040829447 | E33: 12
A34: Cabinet Comptable Exemple | B34: 24000 | C34: 0.027877462 | E34: 4
A35: Assurances Mutuelles Exemple | B35: 12000 | C35: 0.013938731 | E35: 4
A36: Telecom Pro | B36: 5760 | C36: 0.0066905909 | E36: 12
A39: Ancienneté des dettes fournisseurs — 2025 (au 31/12/2025), méthode FIFO
A40: Fournisseur | B40: Solde | C40: Groupe | D40: 0-30 j | E40: 31-60 j | F40: 61-90 j | G40: 91-180 j | H40: 181-365 j | I40: > 1 an
A41: Scierie du Nord | B41: 144759.99 | D41: 72380 | E41: 72379.99 | F41: 0 | G41: 0 | H41: 0 | I41: 0
A42: Quincaillerie Pro Est | B42: 21276.26 | D42: 0 | E42: 0 | F42: 21276.26 | G42: 0 | H42: 0 | I42: 0
A43: Vernis et Finitions | B43: 14400 | D43: 0 | E43: 0 | F43: 0 | G43: 14400 | H43: 0 | I43: 0
A44: SCI Les Halles | B44: 10200 | D44: 10200 | E44: 0 | F44: 0 | G44: 0 | H44: 0 | I44: 0
A45: Cabinet Comptable Exemple | B45: 8300 | D45: 7200 | E45: 0 | F45: 0 | G45: 1100 | H45: 0 | I45: 0
...

Sheet Social_fiscal
A1: Dettes sociales et fiscales : dû comptabilisé / payé en banque
A2: Valeurs calculées par l'application. Doublons d'import écartés ; cotisations des mois de paie non comptabilisée estimées. À confirmer par les relevés des organismes (URSSAF, retraite, prévoyance, mutuelle, compte fiscal).
A4: 2024 (du 01/01/2024 au 31/12/2024)
A5: Organisme | B5: Comptes | C5: Ouverture (corrigée) | D5: Dû comptabilisé | E5: Doublons écartés | F5: Payé en banque | G5: Remboursements reçus | H5: Autres apurements (OD) | I5: Clôture (corrigée) | J5: Estimation mois non comptabilisés | K5: Solde estimé | L5: Dû mensuel moyen | M5: Retard (mois)
A6: URSSAF | B6: 431000 | C6: 18000 | D6: 398883.36 | E6: 0 | F6: 383590.84 | G6: 0 | H6: 0 | I6: 33292.52 | J6: 0 | K6: =I6+J6 | L6: 33277.73 | M6: =IF(L6>1,MAX(0,K6)/L6,"n.d.")
A7: TVA | B7: 445510 | C7: 12000 | D7: 196429.9 | E7: 0 | F7: 193634.04 | G7: 0 | H7: 0 | I7: 14795.86 | J7: 0 | K7: =I7+J7 | L7: 16046.41 | M7: =IF(L7>1,MAX(0,K7)/L7,"n.d.")
A8: Impôt sur les sociétés | B8: 444000 | C8: 0 | D8: 9067.03 | E8: 0 | F8: 0 | G8: 0 | H8: 0 | I8: 9067.03 | J8: 0 | K8: =I8+J8 | L8: 9067.03 | M8: =IF(L8>1,MAX(0,K8)/L8,"n.d.")
A9: Crédits d'impôt comptabilisés en produit (CIR, CII…) | C9: 0
A10: Paie par mois : charges comptabilisées (64) / salaires nets versés en banque
C11: 2024-01 | D11: 2024-02 | E11: 2024-03 | F11: 2024-04 | G11: 2024-05 | H11: 2024-06 | I11: 2024-07 | J11: 2024-08 | K11: 2024-09 | L11: 2024-10 | M11: 2024-11 | N11: 2024-12
A12: Charges de personnel comptabilisées | C12: 74866.36 | D12: 73160.52 | E12: 73610.09 | F12: 74662.95 | G12: 73026.87 | H12: 72685.94 | I12: 74679.04 | J12: 72480.58 | K12: 74960.21 | L12: 73614.28 | M12: 73407.82 | N12: 73867.78
A13: Salaires nets versés (banque) | C13: 41123.78 | D13: 40186.76 | E13: 40433.71 | F13: 41012.04 | G13: 40113.35 | H13: 39926.08 | I13: 41020.88 | J13: 39813.27 | K13: 41175.33 | L13: 40436.01 | M13: 40322.61 | N13: 40575.26
A14: URSSAF : dû / payé | C14: 33743 / 18000 | D14: 32974 / 33743 | E14: 33176 / 32974 | F14: 33651 / 33176 | G14: 32914 / 33651 | H14: 32760 / 32914 | I14: 33658 / 32760 | J14: 32667 / 33658 | K14: 33785 / 32667 | L14: 33178 / 33785 | M14: 33085 / 33178 | N14: 33293 / 33085
A15: TVA : dû / payé | C15: 14131 / 12000 | D15: 14999 / 14131 | E15: 16610 / 14999 | F15: 17878 / 16610 | G15: 18958 / 17878 | H15: 17575 / 18958 | I15: 16019 / 17575 | J15: 11101 / 16019 | K15: 16586 / 11101 | L15: 18966 / 16586 | M15: 18811 / 18966 | N15: 14796 / 18811
A18: 2025 (du 01/01/2025 au 31/12/2025)
A19: Organisme | B19: Comptes | C19: Ouverture (corrigée) | D19: Dû comptabilisé | E19: Doublons écartés | F19: Payé en banque | G19: Remboursements reçus | H19: Autres apurements (OD) | I19: Clôture (corrigée) | J19: Estimation mois non comptabilisés | K19: Solde estimé | L19: Dû mensuel moyen | M19: Retard (mois)
A20: URSSAF | B20: 431000 | C20: 33292.52 | D20: 384973.21 | E20: 0 | F20: 289968.84 | G20: 0 | H20: 0 | I20: 128296.89 | J20: 0 | K20: =I20+J20 | L20: 32062.58 | M20: =IF(L20>1,MAX(0,K20)/L20,"n.d.")
