Workbook

Sheet LISEZMOI
A1: Vestis — Trésorerie historique reconstituée depuis le FEC
A2: Exercices : 2024, 2025. Généré le 19/10/2026.
A4: Méthode | B4: Chaque écriture qui mouvemente un compte de banque (512, 514, 517, 53) est lue par sa contrepartie : 411 = encaissement client, 421 = salaires, 431 = URSSAF, 445 = TVA, 164 = emprunt, etc. Les à-nouveaux ne sont pas des flux : ils donnent la trésorerie d'ouverture.
A5: Reclasser un flux | B5: Flux_detail, colonne M « Surcharge » (jaune) : saisir une catégorie de l'onglet Categories. Tous les tableaux se recalculent.
A6: Limites | B6: Le FEC s'arrête à la dernière saisie du cabinet : les semaines récentes viendront des relevés bancaires. Le solde est comptable, pas le solde de relevé (rapprochement bancaire à vérifier). Les virements via 58 et les comptes d'attente sont signalés dans les contrôles.
A7: Ordre de lecture | B7: 1. Controles 2. Flux_mensuels 3. Solde_quotidien (point bas) 4. Flux_hebdo 5. Delais 6. Recurrences.
A8: Confidentialité | B8: Classeur produit localement : les fichiers n'ont été transmis à aucun serveur.

Sheet Controles
A1: Contrôles de la reconstitution des flux
A2: La trésorerie de fin d'exercice recalculée à partir des flux doit égaler le solde comptable des banques.
A4: Contrôle | B4: 2024 | C4: Statut | D4: 2025 | E4: Statut
A5: Trésorerie d'ouverture (à-nouveaux bancaires) | B5: 85000 | D5: 111111.24
A6: Flux nets de l'exercice (somme des flux détaillés) | B6: =SUMIFS(Flux_detail!$K$2:$K$403,Flux_detail!$D$2:$D$403,"2024") | D6: =SUMIFS(Flux_detail!$K$2:$K$403,Flux_detail!$D$2:$D$403,"2025")
A7: Trésorerie de clôture recalculée | B7: =B5+B6 | D7: =D5+D6
A8: Solde comptable des banques à la clôture | B8: 111111.24 | D8: -152621.97
A9: Écart (doit être nul) | B9: =B7-B8 | C9: =IF(ABS(B9)<=1,"OK","À VOIR") | D9: =D7-D8 | E9: =IF(ABS(D9)<=1,"OK","À VOIR")
A10: Écritures de banque déséquilibrées (montant) | B10: 0 | C10: =IF(ABS(B10)<=1,"OK","À VOIR") | D10: 0 | E10: =IF(ABS(D10)<=1,"OK","À VOIR")
A11: Part des flux non affectés (attente, divers, transit) | B11: 0 | C11: =IF(B11<=0.05,"OK","À VOIR") | D11: 0 | E11: =IF(D11<=0.05,"OK","À VOIR")
A12: Fonds en transit (comptes 58) à la clôture | B12: 0 | C12: =IF(ABS(B12)<=1,"OK","À VOIR") | D12: 0 | E12: =IF(ABS(D12)<=1,"OK","À VOIR")
A13: Nombre de flux reconstitués | B13: 202 | D13: 200
A14: Comptes de banque | B14: 512000 | D14: 512000

Sheet Flux_mensuels
A1: Flux de trésorerie mensuels
A2: Encaissements positifs, décaissements négatifs. Reconstitués depuis les écritures de banque du FEC (contrepartie de chaque écriture).
B3: 2024 | C3: 2024 | D3: 2024 | E3: 2024 | F3: 2024 | G3: 2024 | H3: 2024 | I3: 2024 | J3: 2024 | K3: 2024 | L3: 2024 | M3: 2024 | N3: 2025 | O3: 2025 | P3: 2025 | Q3: 2025 | R3: 2025 | S3: 2025 | T3: 2025 | U3: 2025 | V3: 2025 | W3: 2025 | X3: 2025 | Y3: 2025
A4: En euros | B4: 2024-01 | C4: 2024-02 | D4: 2024-03 | E4: 2024-04 | F4: 2024-05 | G4: 2024-06 | H4: 2024-07 | I4: 2024-08 | J4: 2024-09 | K4: 2024-10 | L4: 2024-11 | M4: 2024-12 | N4: 2025-01 | O4: 2025-02 | P4: 2025-03 | Q4: 2025-04 | R4: 2025-05 | S4: 2025-06 | T4: 2025-07 | U4: 2025-08 | V4: 2025-09 | W4: 2025-10 | X4: 2025-11 | Y4: 2025-12
A5: Flux d'exploitation
A6: Clients | B6: =SUMIFS(Flux_detail!$K$2:$K$403,Flux_detail!$N$2:$N$403,$A6,Flux_detail!$C$2:$C$403,B$4) | C6: =SUMIFS(Flux_detail!$K$2:$K$403,Flux_detail!$N$2:$N$403,$A6,Flux_detail!$C$2:$C$403,C$4) | D6: =SUMIFS(Flux_detail!$K$2:$K$403,Flux_detail!$N$2:$N$403,$A6,Flux_detail!$C$2:$C$403,D$4) | E6: =SUMIFS(Flux_detail!$K$2:$K$403,Flux_detail!$N$2:$N$403,$A6,Flux_detail!$C$2:$C$403,E$4) | F6: =SUMIFS(Flux_detail!$K$2:$K$403,Flux_detail!$N$2:$N$403,$A6,Flux_detail!$C$2:$C$403,F$4) | G6: =SUMIFS(Flux_detail!$K$2:$K$403,Flux_detail!$N$2:$N$403,$A6,Flux_detail!$C$2:$C$403,G$4) | H6: =SUMIFS(Flux_detail!$K$2:$K$403,Flux_detail!$N$2:$N$403,$A6,Flux_detail!$C$2:$C$403,H$4) | I6: =SUMIFS(Flux_detail!$K$2:$K$403,Flux_detail!$N$2:$N$403,$A6,Flux_detail!$C$2:$C$403,I$4) | ... Y6: =SUMIFS(Flux_detail!$K$2:$K$403,Flux_detail!$N$2:$N$403,$A6,Flux_detail!$C$2:$C$403,Y$4)
A7: Fournisseurs et charges externes | B7: =SUMIFS(Flux_detail!$K$2:$K$403,Flux_detail!$N$2:$N$403,$A7,Flux_detail!$C$2:$C$403,B$4) | C7: =SUMIFS(Flux_detail!$K$2:$K$403,Flux_detail!$N$2:$N$403,$A7,Flux_detail!$C$2:$C$403,C$4) | D7: =SUMIFS(Flux_detail!$K$2:$K$403,Flux_detail!$N$2:$N$403,$A7,Flux_detail!$C$2:$C$403,D$4) | E7: =SUMIFS(Flux_detail!$K$2:$K$403,Flux_detail!$N$2:$N$403,$A7,Flux_detail!$C$2:$C$403,E$4) | F7: =SUMIFS(Flux_detail!$K$2:$K$403,Flux_detail!$N$2:$N$403,$A7,Flux_detail!$C$2:$C$403,F$4) | G7: =SUMIFS(Flux_detail!$K$2:$K$403,Flux_detail!$N$2:$N$403,$A7,Flux_detail!$C$2:$C$403,G$4) | H7: =SUMIFS(Flux_detail!$K$2:$K$403,Flux_detail!$N$2:$N$403,$A7,Flux_detail!$C$2:$C$403,H$4) | I7: =SUMIFS(Flux_detail!$K$2:$K$403,Flux_detail!$N$2:$N$403,$A7,Flux_detail!$C$2:$C$403,I$4) | ... Y7: =SUMIFS(Flux_detail!$K$2:$K$403,Flux_detail!$N$2:$N$403,$A7,Flux_detail!$C$2:$C$403,Y$4)
A8: Frais bancaires | B8: =SUMIFS(Flux_detail!$K$2:$K$403,Flux_detail!$N$2:$N$403,$A8,Flux_detail!$C$2:$C$403,B$4) | C8: =SUMIFS(Flux_detail!$K$2:$K$403,Flux_detail!$N$2:$N$403,$A8,Flux_detail!$C$2:$C$403,C$4) | D8: =SUMIFS(Flux_detail!$K$2:$K$403,Flux_detail!$N$2:$N$403,$A8,Flux_detail!$C$2:$C$403,D$4) | E8: =SUMIFS(Flux_detail!$K$2:$K$403,Flux_detail!$N$2:$N$403,$A8,Flux_detail!$C$2:$C$403,E$4) | F8: =SUMIFS(Flux_detail!$K$2:$K$403,Flux_detail!$N$2:$N$403,$A8,Flux_detail!$C$2:$C$403,F$4) | G8: =SUMIFS(Flux_detail!$K$2:$K$403,Flux_detail!$N$2:$N$403,$A8,Flux_detail!$C$2:$C$403,G$4) | H8: =SUMIFS(Flux_detail!$K$2:$K$403,Flux_detail!$N$2:$N$403,$A8,Flux_detail!$C$2:$C$403,H$4) | I8: =SUMIFS(Flux_detail!$K$2:$K$403,Flux_detail!$N$2:$N$403,$A8,Flux_detail!$C$2:$C$403,I$4) | ... Y8: =SUMIFS(Flux_detail!$K$2:$K$403,Flux_detail!$N$2:$N$403,$A8,Flux_detail!$C$2:$C$403,Y$4)
A9: Salaires et personnel | B9: =SUMIFS(Flux_detail!$K$2:$K$403,Flux_detail!$N$2:$N$403,$A9,Flux_detail!$C$2:$C$403,B$4) | C9: =SUMIFS(Flux_detail!$K$2:$K$403,Flux_detail!$N$2:$N$403,$A9,Flux_detail!$C$2:$C$403,C$4) | D9: =SUMIFS(Flux_detail!$K$2:$K$403,Flux_detail!$N$2:$N$403,$A9,Flux_detail!$C$2:$C$403,D$4) | E9: =SUMIFS(Flux_detail!$K$2:$K$403,Flux_detail!$N$2:$N$403,$A9,Flux_detail!$C$2:$C$403,E$4) | F9: =SUMIFS(Flux_detail!$K$2:$K$403,Flux_detail!$N$2:$N$403,$A9,Flux_detail!$C$2:$C$403,F$4) | G9: =SUMIFS(Flux_detail!$K$2:$K$403,Flux_detail!$N$2:$N$403,$A9,Flux_detail!$C$2:$C$403,G$4) | H9: =SUMIFS(Flux_detail!$K$2:$K$403,Flux_detail!$N$2:$N$403,$A9,Flux_detail!$C$2:$C$403,H$4) | I9: =SUMIFS(Flux_detail!$K$2:$K$403,Flux_detail!$N$2:$N$403,$A9,Flux_detail!$C$2:$C$403,I$4) | ... Y9: =SUMIFS(Flux_detail!$K$2:$K$403,Flux_detail!$N$2:$N$403,$A9,Flux_detail!$C$2:$C$403,Y$4)
A10: Charges sociales | B10: =SUMIFS(Flux_detail!$K$2:$K$403,Flux_detail!$N$2:$N$403,$A10,Flux_detail!$C$2:$C$403,B$4) | C10: =SUMIFS(Flux_detail!$K$2:$K$403,Flux_detail!$N$2:$N$403,$A10,Flux_detail!$C$2:$C$403,C$4) | D10: =SUMIFS(Flux_detail!$K$2:$K$403,Flux_detail!$N$2:$N$403,$A10,Flux_detail!$C$2:$C$403,D$4) | E10: =SUMIFS(Flux_detail!$K$2:$K$403,Flux_detail!$N$2:$N$403,$A10,Flux_detail!$C$2:$C$403,E$4) | F10: =SUMIFS(Flux_detail!$K$2:$K$403,Flux_detail!$N$2:$N$403,$A10,Flux_detail!$C$2:$C$403,F$4) | G10: =SUMIFS(Flux_detail!$K$2:$K$403,Flux_detail!$N$2:$N$403,$A10,Flux_detail!$C$2:$C$403,G$4) | H10: =SUMIFS(Flux_detail!$K$2:$K$403,Flux_detail!$N$2:$N$403,$A10,Flux_detail!$C$2:$C$403,H$4) | I10: =SUMIFS(Flux_detail!$K$2:$K$403,Flux_detail!$N$2:$N$403,$A10,Flux_detail!$C$2:$C$403,I$4) | ... Y10: =SUMIFS(Flux_detail!$K$2:$K$403,Flux_detail!$N$2:$N$403,$A10,Flux_detail!$C$2:$C$403,Y$4)
A11: TVA | B11: =SUMIFS(Flux_detail!$K$2:$K$403,Flux_detail!$N$2:$N$403,$A11,Flux_detail!$C$2:$C$403,B$4) | C11: =SUMIFS(Flux_detail!$K$2:$K$403,Flux_detail!$N$2:$N$403,$A11,Flux_detail!$C$2:$C$403,C$4) | D11: =SUMIFS(Flux_detail!$K$2:$K$403,Flux_detail!$N$2:$N$403,$A11,Flux_detail!$C$2:$C$403,D$4) | E11: =SUMIFS(Flux_detail!$K$2:$K$403,Flux_detail!$N$2:$N$403,$A11,Flux_detail!$C$2:$C$403,E$4) | F11: =SUMIFS(Flux_detail!$K$2:$K$403,Flux_detail!$N$2:$N$403,$A11,Flux_detail!$C$2:$C$403,F$4) | G11: =SUMIFS(Flux_detail!$K$2:$K$403,Flux_detail!$N$2:$N$403,$A11,Flux_detail!$C$2:$C$403,G$4) | H11: =SUMIFS(Flux_detail!$K$2:$K$403,Flux_detail!$N$2:$N$403,$A11,Flux_detail!$C$2:$C$403,H$4) | I11: =SUMIFS(Flux_detail!$K$2:$K$403,Flux_detail!$N$2:$N$403,$A11,Flux_detail!$C$2:$C$403,I$4) | ... Y11: =SUMIFS(Flux_detail!$K$2:$K$403,Flux_detail!$N$2:$N$403,$A11,Flux_detail!$C$2:$C$403,Y$4)
A12: Impôt sur les sociétés | B12: =SUMIFS(Flux_detail!$K$2:$K$403,Flux_detail!$N$2:$N$403,$A12,Flux_detail!$C$2:$C$403,B$4) | C12: =SUMIFS(Flux_detail!$K$2:$K$403,Flux_detail!$N$2:$N$403,$A12,Flux_detail!$C$2:$C$403,C$4) | D12: =SUMIFS(Flux_detail!$K$2:$K$403,Flux_detail!$N$2:$N$403,$A12,Flux_detail!$C$2:$C$403,D$4) | E12: =SUMIFS(Flux_detail!$K$2:$K$403,Flux_detail!$N$2:$N$403,$A12,Flux_detail!$C$2:$C$403,E$4) | F12: =SUMIFS(Flux_detail!$K$2:$K$403,Flux_detail!$N$2:$N$403,$A12,Flux_detail!$C$2:$C$403,F$4) | G12: =SUMIFS(Flux_detail!$K$2:$K$403,Flux_detail!$N$2:$N$403,$A12,Flux_detail!$C$2:$C$403,G$4) | H12: =SUMIFS(Flux_detail!$K$2:$K$403,Flux_detail!$N$2:$N$403,$A12,Flux_detail!$C$2:$C$403,H$4) | I12: =SUMIFS(Flux_detail!$K$2:$K$403,Flux_detail!$N$2:$N$403,$A12,Flux_detail!$C$2:$C$403,I$4) | ... Y12: =SUMIFS(Flux_detail!$K$2:$K$403,Flux_detail!$N$2:$N$403,$A12,Flux_detail!$C$2:$C$403,Y$4)
A13: Autres impôts et taxes | B13: =SUMIFS(Flux_detail!$K$2:$K$403,Flux_detail!$N$2:$N$403,$A13,Flux_detail!$C$2:$C$403,B$4) | C13: =SUMIFS(Flux_detail!$K$2:$K$403,Flux_detail!$N$2:$N$403,$A13,Flux_detail!$C$2:$C$403,C$4) | D13: =SUMIFS(Flux_detail!$K$2:$K$403,Flux_detail!$N$2:$N$403,$A13,Flux_detail!$C$2:$C$403,D$4) | E13: =SUMIFS(Flux_detail!$K$2:$K$403,Flux_detail!$N$2:$N$403,$A13,Flux_detail!$C$2:$C$403,E$4) | F13: =SUMIFS(Flux_detail!$K$2:$K$403,Flux_detail!$N$2:$N$403,$A13,Flux_detail!$C$2:$C$403,F$4) | G13: =SUMIFS(Flux_detail!$K$2:$K$403,Flux_detail!$N$2:$N$403,$A13,Flux_detail!$C$2:$C$403,G$4) | H13: =SUMIFS(Flux_detail!$K$2:$K$403,Flux_detail!$N$2:$N$403,$A13,Flux_detail!$C$2:$C$403,H$4) | I13: =SUMIFS(Flux_detail!$K$2:$K$403,Flux_detail!$N$2:$N$403,$A13,Flux_detail!$C$2:$C$403,I$4) | ... Y13: =SUMIFS(Flux_detail!$K$2:$K$403,Flux_detail!$N$2:$N$403,$A13,Flux_detail!$C$2:$C$403,Y$4)
A14: Total flux d'exploitation | B14: =SUMIFS(Flux_detail!$K$2:$K$403,Flux_detail!$O$2:$O$403,"EXPL",Flux_detail!$C$2:$C$403,B$4) | C14: =SUMIFS(Flux_detail!$K$2:$K$403,Flux_detail!$O$2:$O$403,"EXPL",Flux_detail!$C$2:$C$403,C$4) | D14: =SUMIFS(Flux_detail!$K$2:$K$403,Flux_detail!$O$2:$O$403,"EXPL",Flux_detail!$C$2:$C$403,D$4) | E14: =SUMIFS(Flux_detail!$K$2:$K$403,Flux_detail!$O$2:$O$403,"EXPL",Flux_detail!$C$2:$C$403,E$4) | F14: =SUMIFS(Flux_detail!$K$2:$K$403,Flux_detail!$O$2:$O$403,"EXPL",Flux_detail!$C$2:$C$403,F$4) | G14: =SUMIFS(Flux_detail!$K$2:$K$403,Flux_detail!$O$2:$O$403,"EXPL",Flux_detail!$C$2:$C$403,G$4) | H14: =SUMIFS(Flux_detail!$K$2:$K$403,Flux_detail!$O$2:$O$403,"EXPL",Flux_detail!$C$2:$C$403,H$4) | I14: =SUMIFS(Flux_detail!$K$2:$K$403,Flux_detail!$O$2:$O$403,"EXPL",Flux_detail!$C$2:$C$403,I$4) | ... Y14: =SUMIFS(Flux_detail!$K$2:$K$403,Flux_detail!$O$2:$O$403,"EXPL",Flux_detail!$C$2:$C$403,Y$4)
A16: Flux de financement
A17: Emprunts - capital | B17: =SUMIFS(Flux_detail!$K$2:$K$403,Flux_detail!$N$2:$N$403,$A17,Flux_detail!$C$2:$C$403,B$4) | C17: =SUMIFS(Flux_detail!$K$2:$K$403,Flux_detail!$N$2:$N$403,$A17,Flux_detail!$C$2:$C$403,C$4) | D17: =SUMIFS(Flux_detail!$K$2:$K$403,Flux_detail!$N$2:$N$403,$A17,Flux_detail!$C$2:$C$403,D$4) | E17: =SUMIFS(Flux_detail!$K$2:$K$403,Flux_detail!$N$2:$N$403,$A17,Flux_detail!$C$2:$C$403,E$4) | F17: =SUMIFS(Flux_detail!$K$2:$K$403,Flux_detail!$N$2:$N$403,$A17,Flux_detail!$C$2:$C$403,F$4) | G17: =SUMIFS(Flux_detail!$K$2:$K$403,Flux_detail!$N$2:$N$403,$A17,Flux_detail!$C$2:$C$403,G$4) | H17: =SUMIFS(Flux_detail!$K$2:$K$403,Flux_detail!$N$2:$N$403,$A17,Flux_detail!$C$2:$C$403,H$4) | I17: =SUMIFS(Flux_detail!$K$2:$K$403,Flux_detail!$N$2:$N$403,$A17,Flux_detail!$C$2:$C$403,I$4) | ... Y17: =SUMIFS(Flux_detail!$K$2:$K$403,Flux_detail!$N$2:$N$403,$A17,Flux_detail!$C$2:$C$403,Y$4)
A18: Intérêts et charges financières | B18: =SUMIFS(Flux_detail!$K$2:$K$403,Flux_detail!$N$2:$N$403,$A18,Flux_detail!$C$2:$C$403,B$4) | C18: =SUMIFS(Flux_detail!$K$2:$K$403,Flux_detail!$N$2:$N$403,$A18,Flux_detail!$C$2:$C$403,C$4) | D18: =SUMIFS(Flux_detail!$K$2:$K$403,Flux_detail!$N$2:$N$403,$A18,Flux_detail!$C$2:$C$403,D$4) | E18: =SUMIFS(Flux_detail!$K$2:$K$403,Flux_detail!$N$2:$N$403,$A18,Flux_detail!$C$2:$C$403,E$4) | F18: =SUMIFS(Flux_detail!$K$2:$K$403,Flux_detail!$N$2:$N$403,$A18,Flux_detail!$C$2:$C$403,F$4) | G18: =SUMIFS(Flux_detail!$K$2:$K$403,Flux_detail!$N$2:$N$403,$A18,Flux_detail!$C$2:$C$403,G$4) | H18: =SUMIFS(Flux_detail!$K$2:$K$403,Flux_detail!$N$2:$N$403,$A18,Flux_detail!$C$2:$C$403,H$4) | I18: =SUMIFS(Flux_detail!$K$2:$K$403,Flux_detail!$N$2:$N$403,$A18,Flux_detail!$C$2:$C$403,I$4) | ... Y18: =SUMIFS(Flux_detail!$K$2:$K$403,Flux_detail!$N$2:$N$403,$A18,Flux_detail!$C$2:$C$403,Y$4)
A19: Associés et groupe | B19: =SUMIFS(Flux_detail!$K$2:$K$403,Flux_detail!$N$2:$N$403,$A19,Flux_detail!$C$2:$C$403,B$4) | C19: =SUMIFS(Flux_detail!$K$2:$K$403,Flux_detail!$N$2:$N$403,$A19,Flux_detail!$C$2:$C$403,C$4) | D19: =SUMIFS(Flux_detail!$K$2:$K$403,Flux_detail!$N$2:$N$403,$A19,Flux_detail!$C$2:$C$403,D$4) | E19: =SUMIFS(Flux_detail!$K$2:$K$403,Flux_detail!$N$2:$N$403,$A19,Flux_detail!$C$2:$C$403,E$4) | F19: =SUMIFS(Flux_detail!$K$2:$K$403,Flux_detail!$N$2:$N$403,$A19,Flux_detail!$C$2:$C$403,F$4) | G19: =SUMIFS(Flux_detail!$K$2:$K$403,Flux_detail!$N$2:$N$403,$A19,Flux_detail!$C$2:$C$403,G$4) | H19: =SUMIFS(Flux_detail!$K$2:$K$403,Flux_detail!$N$2:$N$403,$A19,Flux_detail!$C$2:$C$403,H$4) | I19: =SUMIFS(Flux_detail!$K$2:$K$403,Flux_detail!$N$2:$N$403,$A19,Flux_detail!$C$2:$C$403,I$4) | ... Y19: =SUMIFS(Flux_detail!$K$2:$K$403,Flux_detail!$N$2:$N$403,$A19,Flux_detail!$C$2:$C$403,Y$4)
A20: Total flux de financement | B20: =SUMIFS(Flux_detail!$K$2:$K$403,Flux_detail!$O$2:$O$403,"FIN",Flux_detail!$C$2:$C$403,B$4) | C20: =SUMIFS(Flux_detail!$K$2:$K$403,Flux_detail!$O$2:$O$403,"FIN",Flux_detail!$C$2:$C$403,C$4) | D20: =SUMIFS(Flux_detail!$K$2:$K$403,Flux_detail!$O$2:$O$403,"FIN",Flux_detail!$C$2:$C$403,D$4) | E20: =SUMIFS(Flux_detail!$K$2:$K$403,Flux_detail!$O$2:$O$403,"FIN",Flux_detail!$C$2:$C$403,E$4) | F20: =SUMIFS(Flux_detail!$K$2:$K$403,Flux_detail!$O$2:$O$403,"FIN",Flux_detail!$C$2:$C$403,F$4) | G20: =SUMIFS(Flux_detail!$K$2:$K$403,Flux_detail!$O$2:$O$403,"FIN",Flux_detail!$C$2:$C$403,G$4) | H20: =SUMIFS(Flux_detail!$K$2:$K$403,Flux_detail!$O$2:$O$403,"FIN",Flux_detail!$C$2:$C$403,H$4) | I20: =SUMIFS(Flux_detail!$K$2:$K$403,Flux_detail!$O$2:$O$403,"FIN",Flux_detail!$C$2:$C$403,I$4) | ... Y20: =SUMIFS(Flux_detail!$K$2:$K$403,Flux_detail!$O$2:$O$403,"FIN",Flux_detail!$C$2:$C$403,Y$4)
A22: VARIATION DE TRÉSORERIE | B22: =SUMIFS(Flux_detail!$K$2:$K$403,Flux_detail!$C$2:$C$403,B$4) | C22: =SUMIFS(Flux_detail!$K$2:$K$403,Flux_detail!$C$2:$C$403,C$4) | D22: =SUMIFS(Flux_detail!$K$2:$K$403,Flux_detail!$C$2:$C$403,D$4) | E22: =SUMIFS(Flux_detail!$K$2:$K$403,Flux_detail!$C$2:$C$403,E$4) | F22: =SUMIFS(Flux_detail!$K$2:$K$403,Flux_detail!$C$2:$C$403,F$4) | G22: =SUMIFS(Flux_detail!$K$2:$K$403,Flux_detail!$C$2:$C$403,G$4) | H22: =SUMIFS(Flux_detail!$K$2:$K$403,Flux_detail!$C$2:$C$403,H$4) | I22: =SUMIFS(Flux_detail!$K$2:$K$403,Flux_detail!$C$2:$C$403,I$4) | ... Y22: =SUMIFS(Flux_detail!$K$2:$K$403,Flux_detail!$C$2:$C$403,Y$4)
A24: Trésorerie début de mois | B24: 85000 | C24: =B25 | D24: =C25 | E24: =D25 | F24: =E25 | G24: =F25 | H24: =G25 | I24: =H25 | J24: =I25 | ... M24: =L25 | N24: 111111.24 | O24: =N25 | P24: =O25 | Q24: =P25 | R24: =Q25 | S24: =R25 | T24: =S25 | U24: =T25 | V24: =U25 | ... Y24: =X25
A25: Trésorerie fin de mois (calculée) | B25: =B24+B22 | C25: =C24+C22 | D25: =D24+D22 | E25: =E24+E22 | F25: =F24+F22 | G25: =G24+G22 | H25: =H24+H22 | I25: =I24+I22 | ... Y25: =Y24+Y22
A26: Trésorerie fin de mois (comptable, contrôle) | B26: 110023.94 | C26: 102329 | D26: 48747.98 | E26: 95305.65 | F26: -21773.84 | G26: 122831.59 | H26: 115988.87 | I26: 124609.33 | J26: 118507.3 | K26: 32377.97 | L26: 127978.73 | M26: 111111.24 | N26: 96813.86 | O26: 27235.8 | P26: 3791.5 | Q26: -50695.23 | R26: -73747.36 | S26: -36030.33 | T26: -20597.29 | U26: -143681.77 | V26: -157121.59 | W26: -104050.96 | X26: -82041.16 | Y26: -152621.97
A27: Écart | B27: =B25-B26 | C27: =C25-C26 | D27: =D25-D26 | E27: =E25-E26 | F27: =F25-F26 | G27: =G25-G26 | H27: =H25-H26 | I27: =I25-I26 | ... Y27: =Y25-Y26
A28: Point bas du mois (solde quotidien) | B28: =_xlfn.MINIFS(Solde_quotidien!$G:$G,Solde_quotidien!$D:$D,B$4) | C28: =_xlfn.MINIFS(Solde_quotidien!$G:$G,Solde_quotidien!$D:$D,C$4) | D28: =_xlfn.MINIFS(Solde_quotidien!$G:$G,Solde_quotidien!$D:$D,D$4) | E28: =_xlfn.MINIFS(Solde_quotidien!$G:$G,Solde_quotidien!$D:$D,E$4) | F28: =_xlfn.MINIFS(Solde_quotidien!$G:$G,Solde_quotidien!$D:$D,F$4) | G28: =_xlfn.MINIFS(Solde_quotidien!$G:$G,Solde_quotidien!$D:$D,G$4) | H28: =_xlfn.MINIFS(Solde_quotidien!$G:$G,Solde_quotidien!$D:$D,H$4) | I28: =_xlfn.MINIFS(Solde_quotidien!$G:$G,Solde_quotidien!$D:$D,I$4) | ... Y28: =_xlfn.MINIFS(Solde_quotidien!$G:$G,Solde_quotidien!$D:$D,Y$4)
A29: La première colonne de chaque exercice repart des à-nouveaux bancaires (bleu). Le solde de fin de mois masque souvent un point bas plus profond en cours de mois (salaires, URSSAF).

Sheet Flux_hebdo
A1: Flux de trésorerie hebdomadaires — 52 dernières semaines des données
A2: Base historique du prévisionnel à 13 semaines : rythme des encaissements et des décaissements par nature.
B3: 45663 | C3: 45670 | D3: 45677 | E3: 45684 | F3: 45691 | G3: 45698 | H3: 45705 | I3: 45712 | J3: 45719 | K3: 45726 | L3: 45733 | M3: 45740 | N3: 45747 | O3: 45754 | P3: 45761 | Q3: 45768 | R3: 45775 | S3: 45782 | T3: 45789 | U3: 45796 | V3: 45803 | W3: 45810 | X3: 45817 | Y3: 45824 | Z3: 45831 | AA3: 45838 | AB3: 45845 | AC3: 45852 | AD3: 45859 | AE3: 45866 | AF3: 45873 | AG3: 45880 | AH3: 45887 | AI3: 45894 | AJ3: 45901 | AK3: 45908 | AL3: 45915 | AM3: 45922 | AN3: 45929 | AO3: 45936 | AP3: 45943 | AQ3: 45950 | AR3: 45957 | AS3: 45964 | AT3: 45971 | AU3: 45978 | AV3: 45985 | AW3: 45992 | AX3: 45999 | AY3: 46006 | AZ3: 46013 | BA3: 46020
A4: En euros | B4: 2025-S02 | C4: 2025-S03 | D4: 2025-S04 | E4: 2025-S05 | F4: 2025-S06 | G4: 2025-S07 | H4: 2025-S08 | I4: 2025-S09 | J4: 2025-S10 | K4: 2025-S11 | L4: 2025-S12 | M4: 2025-S13 | N4: 2025-S14 | O4: 2025-S15 | P4: 2025-S16 | Q4: 2025-S17 | R4: 2025-S18 | S4: 2025-S19 | T4: 2025-S20 | U4: 2025-S21 | V4: 2025-S22 | W4: 2025-S23 | X4: 2025-S24 | Y4: 2025-S25 | Z4: 2025-S26 | AA4: 2025-S27 | AB4: 2025-S28 | AC4: 2025-S29 | AD4: 2025-S30 | AE4: 2025-S31 | AF4: 2025-S32 | AG4: 2025-S33 | AH4: 2025-S34 | AI4: 2025-S35 | AJ4: 2025-S36 | AK4: 2025-S37 | AL4: 2025-S38 | AM4: 2025-S39 | AN4: 2025-S40 | AO4: 2025-S41 | AP4: 2025-S42 | AQ4: 2025-S43 | AR4: 2025-S44 | AS4: 2025-S45 | AT4: 2025-S46 | AU4: 2025-S47 | AV4: 2025-S48 | AW4: 2025-S49 | AX4: 2025-S50 | AY4: 2025-S51 | AZ4: 2025-S52 | BA4: 2026-S01
A5: Flux d'exploitation
A6: Clients | B6: =SUMIFS(Flux_detail!$K$2:$K$403,Flux_detail!$N$2:$N$403,$A6,Flux_detail!$B$2:$B$403,B$4) | C6: =SUMIFS(Flux_detail!$K$2:$K$403,Flux_detail!$N$2:$N$403,$A6,Flux_detail!$B$2:$B$403,C$4) | D6: =SUMIFS(Flux_detail!$K$2:$K$403,Flux_detail!$N$2:$N$403,$A6,Flux_detail!$B$2:$B$403,D$4) | E6: =SUMIFS(Flux_detail!$K$2:$K$403,Flux_detail!$N$2:$N$403,$A6,Flux_detail!$B$2:$B$403,E$4) | F6: =SUMIFS(Flux_detail!$K$2:$K$403,Flux_detail!$N$2:$N$403,$A6,Flux_detail!$B$2:$B$403,F$4) | G6: =SUMIFS(Flux_detail!$K$2:$K$403,Flux_detail!$N$2:$N$403,$A6,Flux_detail!$B$2:$B$403,G$4) | H6: =SUMIFS(Flux_detail!$K$2:$K$403,Flux_detail!$N$2:$N$403,$A6,Flux_detail!$B$2:$B$403,H$4) | I6: =SUMIFS(Flux_detail!$K$2:$K$403,Flux_detail!$N$2:$N$403,$A6,Flux_detail!$B$2:$B$403,I$4) | ... BA6: =SUMIFS(Flux_detail!$K$2:$K$403,Flux_detail!$N$2:$N$403,$A6,Flux_detail!$B$2:$B$403,BA$4)
A7: Fournisseurs et charges externes | B7: =SUMIFS(Flux_detail!$K$2:$K$403,Flux_detail!$N$2:$N$403,$A7,Flux_detail!$B$2:$B$403,B$4) | C7: =SUMIFS(Flux_detail!$K$2:$K$403,Flux_detail!$N$2:$N$403,$A7,Flux_detail!$B$2:$B$403,C$4) | D7: =SUMIFS(Flux_detail!$K$2:$K$403,Flux_detail!$N$2:$N$403,$A7,Flux_detail!$B$2:$B$403,D$4) | E7: =SUMIFS(Flux_detail!$K$2:$K$403,Flux_detail!$N$2:$N$403,$A7,Flux_detail!$B$2:$B$403,E$4) | F7: =SUMIFS(Flux_detail!$K$2:$K$403,Flux_detail!$N$2:$N$403,$A7,Flux_detail!$B$2:$B$403,F$4) | G7: =SUMIFS(Flux_detail!$K$2:$K$403,Flux_detail!$N$2:$N$403,$A7,Flux_detail!$B$2:$B$403,G$4) | H7: =SUMIFS(Flux_detail!$K$2:$K$403,Flux_detail!$N$2:$N$403,$A7,Flux_detail!$B$2:$B$403,H$4) | I7: =SUMIFS(Flux_detail!$K$2:$K$403,Flux_detail!$N$2:$N$403,$A7,Flux_detail!$B$2:$B$403,I$4) | ... BA7: =SUMIFS(Flux_detail!$K$2:$K$403,Flux_detail!$N$2:$N$403,$A7,Flux_detail!$B$2:$B$403,BA$4)
A8: Frais bancaires | B8: =SUMIFS(Flux_detail!$K$2:$K$403,Flux_detail!$N$2:$N$403,$A8,Flux_detail!$B$2:$B$403,B$4) | C8: =SUMIFS(Flux_detail!$K$2:$K$403,Flux_detail!$N$2:$N$403,$A8,Flux_detail!$B$2:$B$403,C$4) | D8: =SUMIFS(Flux_detail!$K$2:$K$403,Flux_detail!$N$2:$N$403,$A8,Flux_detail!$B$2:$B$403,D$4) | E8: =SUMIFS(Flux_detail!$K$2:$K$403,Flux_detail!$N$2:$N$403,$A8,Flux_detail!$B$2:$B$403,E$4) | F8: =SUMIFS(Flux_detail!$K$2:$K$403,Flux_detail!$N$2:$N$403,$A8,Flux_detail!$B$2:$B$403,F$4) | G8: =SUMIFS(Flux_detail!$K$2:$K$403,Flux_detail!$N$2:$N$403,$A8,Flux_detail!$B$2:$B$403,G$4) | H8: =SUMIFS(Flux_detail!$K$2:$K$403,Flux_detail!$N$2:$N$403,$A8,Flux_detail!$B$2:$B$403,H$4) | I8: =SUMIFS(Flux_detail!$K$2:$K$403,Flux_detail!$N$2:$N$403,$A8,Flux_detail!$B$2:$B$403,I$4) | ... BA8: =SUMIFS(Flux_detail!$K$2:$K$403,Flux_detail!$N$2:$N$403,$A8,Flux_detail!$B$2:$B$403,BA$4)
A9: Salaires et personnel | B9: =SUMIFS(Flux_detail!$K$2:$K$403,Flux_detail!$N$2:$N$403,$A9,Flux_detail!$B$2:$B$403,B$4) | C9: =SUMIFS(Flux_detail!$K$2:$K$403,Flux_detail!$N$2:$N$403,$A9,Flux_detail!$B$2:$B$403,C$4) | D9: =SUMIFS(Flux_detail!$K$2:$K$403,Flux_detail!$N$2:$N$403,$A9,Flux_detail!$B$2:$B$403,D$4) | E9: =SUMIFS(Flux_detail!$K$2:$K$403,Flux_detail!$N$2:$N$403,$A9,Flux_detail!$B$2:$B$403,E$4) | F9: =SUMIFS(Flux_detail!$K$2:$K$403,Flux_detail!$N$2:$N$403,$A9,Flux_detail!$B$2:$B$403,F$4) | G9: =SUMIFS(Flux_detail!$K$2:$K$403,Flux_detail!$N$2:$N$403,$A9,Flux_detail!$B$2:$B$403,G$4) | H9: =SUMIFS(Flux_detail!$K$2:$K$403,Flux_detail!$N$2:$N$403,$A9,Flux_detail!$B$2:$B$403,H$4) | I9: =SUMIFS(Flux_detail!$K$2:$K$403,Flux_detail!$N$2:$N$403,$A9,Flux_detail!$B$2:$B$403,I$4) | ... BA9: =SUMIFS(Flux_detail!$K$2:$K$403,Flux_detail!$N$2:$N$403,$A9,Flux_detail!$B$2:$B$403,BA$4)
A10: Charges sociales | B10: =SUMIFS(Flux_detail!$K$2:$K$403,Flux_detail!$N$2:$N$403,$A10,Flux_detail!$B$2:$B$403,B$4) | C10: =SUMIFS(Flux_detail!$K$2:$K$403,Flux_detail!$N$2:$N$403,$A10,Flux_detail!$B$2:$B$403,C$4) | D10: =SUMIFS(Flux_detail!$K$2:$K$403,Flux_detail!$N$2:$N$403,$A10,Flux_detail!$B$2:$B$403,D$4) | E10: =SUMIFS(Flux_detail!$K$2:$K$403,Flux_detail!$N$2:$N$403,$A10,Flux_detail!$B$2:$B$403,E$4) | F10: =SUMIFS(Flux_detail!$K$2:$K$403,Flux_detail!$N$2:$N$403,$A10,Flux_detail!$B$2:$B$403,F$4) | G10: =SUMIFS(Flux_detail!$K$2:$K$403,Flux_detail!$N$2:$N$403,$A10,Flux_detail!$B$2:$B$403,G$4) | H10: =SUMIFS(Flux_detail!$K$2:$K$403,Flux_detail!$N$2:$N$403,$A10,Flux_detail!$B$2:$B$403,H$4) | I10: =SUMIFS(Flux_detail!$K$2:$K$403,Flux_detail!$N$2:$N$403,$A10,Flux_detail!$B$2:$B$403,I$4) | ... BA10: =SUMIFS(Flux_detail!$K$2:$K$403,Flux_detail!$N$2:$N$403,$A10,Flux_detail!$B$2:$B$403,BA$4)
A11: TVA | B11: =SUMIFS(Flux_detail!$K$2:$K$403,Flux_detail!$N$2:$N$403,$A11,Flux_detail!$B$2:$B$403,B$4) | C11: =SUMIFS(Flux_detail!$K$2:$K$403,Flux_detail!$N$2:$N$403,$A11,Flux_detail!$B$2:$B$403,C$4) | D11: =SUMIFS(Flux_detail!$K$2:$K$403,Flux_detail!$N$2:$N$403,$A11,Flux_detail!$B$2:$B$403,D$4) | E11: =SUMIFS(Flux_detail!$K$2:$K$403,Flux_detail!$N$2:$N$403,$A11,Flux_detail!$B$2:$B$403,E$4) | F11: =SUMIFS(Flux_detail!$K$2:$K$403,Flux_detail!$N$2:$N$403,$A11,Flux_detail!$B$2:$B$403,F$4) | G11: =SUMIFS(Flux_detail!$K$2:$K$403,Flux_detail!$N$2:$N$403,$A11,Flux_detail!$B$2:$B$403,G$4) | H11: =SUMIFS(Flux_detail!$K$2:$K$403,Flux_detail!$N$2:$N$403,$A11,Flux_detail!$B$2:$B$403,H$4) | I11: =SUMIFS(Flux_detail!$K$2:$K$403,Flux_detail!$N$2:$N$403,$A11,Flux_detail!$B$2:$B$403,I$4) | ... BA11: =SUMIFS(Flux_detail!$K$2:$K$403,Flux_detail!$N$2:$N$403,$A11,Flux_detail!$B$2:$B$403,BA$4)
A12: Impôt sur les sociétés | B12: =SUMIFS(Flux_detail!$K$2:$K$403,Flux_detail!$N$2:$N$403,$A12,Flux_detail!$B$2:$B$403,B$4) | C12: =SUMIFS(Flux_detail!$K$2:$K$403,Flux_detail!$N$2:$N$403,$A12,Flux_detail!$B$2:$B$403,C$4) | D12: =SUMIFS(Flux_detail!$K$2:$K$403,Flux_detail!$N$2:$N$403,$A12,Flux_detail!$B$2:$B$403,D$4) | E12: =SUMIFS(Flux_detail!$K$2:$K$403,Flux_detail!$N$2:$N$403,$A12,Flux_detail!$B$2:$B$403,E$4) | F12: =SUMIFS(Flux_detail!$K$2:$K$403,Flux_detail!$N$2:$N$403,$A12,Flux_detail!$B$2:$B$403,F$4) | G12: =SUMIFS(Flux_detail!$K$2:$K$403,Flux_detail!$N$2:$N$403,$A12,Flux_detail!$B$2:$B$403,G$4) | H12: =SUMIFS(Flux_detail!$K$2:$K$403,Flux_detail!$N$2:$N$403,$A12,Flux_detail!$B$2:$B$403,H$4) | I12: =SUMIFS(Flux_detail!$K$2:$K$403,Flux_detail!$N$2:$N$403,$A12,Flux_detail!$B$2:$B$403,I$4) | ... BA12: =SUMIFS(Flux_detail!$K$2:$K$403,Flux_detail!$N$2:$N$403,$A12,Flux_detail!$B$2:$B$403,BA$4)
A13: Autres impôts et taxes | B13: =SUMIFS(Flux_detail!$K$2:$K$403,Flux_detail!$N$2:$N$403,$A13,Flux_detail!$B$2:$B$403,B$4) | C13: =SUMIFS(Flux_detail!$K$2:$K$403,Flux_detail!$N$2:$N$403,$A13,Flux_detail!$B$2:$B$403,C$4) | D13: =SUMIFS(Flux_detail!$K$2:$K$403,Flux_detail!$N$2:$N$403,$A13,Flux_detail!$B$2:$B$403,D$4) | E13: =SUMIFS(Flux_detail!$K$2:$K$403,Flux_detail!$N$2:$N$403,$A13,Flux_detail!$B$2:$B$403,E$4) | F13: =SUMIFS(Flux_detail!$K$2:$K$403,Flux_detail!$N$2:$N$403,$A13,Flux_detail!$B$2:$B$403,F$4) | G13: =SUMIFS(Flux_detail!$K$2:$K$403,Flux_detail!$N$2:$N$403,$A13,Flux_detail!$B$2:$B$403,G$4) | H13: =SUMIFS(Flux_detail!$K$2:$K$403,Flux_detail!$N$2:$N$403,$A13,Flux_detail!$B$2:$B$403,H$4) | I13: =SUMIFS(Flux_detail!$K$2:$K$403,Flux_detail!$N$2:$N$403,$A13,Flux_detail!$B$2:$B$403,I$4) | ... BA13: =SUMIFS(Flux_detail!$K$2:$K$403,Flux_detail!$N$2:$N$403,$A13,Flux_detail!$B$2:$B$403,BA$4)
A14: Total flux d'exploitation | B14: =SUMIFS(Flux_detail!$K$2:$K$403,Flux_detail!$O$2:$O$403,"EXPL",Flux_detail!$B$2:$B$403,B$4) | C14: =SUMIFS(Flux_detail!$K$2:$K$403,Flux_detail!$O$2:$O$403,"EXPL",Flux_detail!$B$2:$B$403,C$4) | D14: =SUMIFS(Flux_detail!$K$2:$K$403,Flux_detail!$O$2:$O$403,"EXPL",Flux_detail!$B$2:$B$403,D$4) | E14: =SUMIFS(Flux_detail!$K$2:$K$403,Flux_detail!$O$2:$O$403,"EXPL",Flux_detail!$B$2:$B$403,E$4) | F14: =SUMIFS(Flux_detail!$K$2:$K$403,Flux_detail!$O$2:$O$403,"EXPL",Flux_detail!$B$2:$B$403,F$4) | G14: =SUMIFS(Flux_detail!$K$2:$K$403,Flux_detail!$O$2:$O$403,"EXPL",Flux_detail!$B$2:$B$403,G$4) | H14: =SUMIFS(Flux_detail!$K$2:$K$403,Flux_detail!$O$2:$O$403,"EXPL",Flux_detail!$B$2:$B$403,H$4) | I14: =SUMIFS(Flux_detail!$K$2:$K$403,Flux_detail!$O$2:$O$403,"EXPL",Flux_detail!$B$2:$B$403,I$4) | ... BA14: =SUMIFS(Flux_detail!$K$2:$K$403,Flux_detail!$O$2:$O$403,"EXPL",Flux_detail!$B$2:$B$403,BA$4)
A16: Flux de financement
A17: Emprunts - capital | B17: =SUMIFS(Flux_detail!$K$2:$K$403,Flux_detail!$N$2:$N$403,$A17,Flux_detail!$B$2:$B$403,B$4) | C17: =SUMIFS(Flux_detail!$K$2:$K$403,Flux_detail!$N$2:$N$403,$A17,Flux_detail!$B$2:$B$403,C$4) | D17: =SUMIFS(Flux_detail!$K$2:$K$403,Flux_detail!$N$2:$N$403,$A17,Flux_detail!$B$2:$B$403,D$4) | E17: =SUMIFS(Flux_detail!$K$2:$K$403,Flux_detail!$N$2:$N$403,$A17,Flux_detail!$B$2:$B$403,E$4) | F17: =SUMIFS(Flux_detail!$K$2:$K$403,Flux_detail!$N$2:$N$403,$A17,Flux_detail!$B$2:$B$403,F$4) | G17: =SUMIFS(Flux_detail!$K$2:$K$403,Flux_detail!$N$2:$N$403,$A17,Flux_detail!$B$2:$B$403,G$4) | H17: =SUMIFS(Flux_detail!$K$2:$K$403,Flux_detail!$N$2:$N$403,$A17,Flux_detail!$B$2:$B$403,H$4) | I17: =SUMIFS(Flux_detail!$K$2:$K$403,Flux_detail!$N$2:$N$403,$A17,Flux_detail!$B$2:$B$403,I$4) | ... BA17: =SUMIFS(Flux_detail!$K$2:$K$403,Flux_detail!$N$2:$N$403,$A17,Flux_detail!$B$2:$B$403,BA$4)
A18: Intérêts et charges financières | B18: =SUMIFS(Flux_detail!$K$2:$K$403,Flux_detail!$N$2:$N$403,$A18,Flux_detail!$B$2:$B$403,B$4) | C18: =SUMIFS(Flux_detail!$K$2:$K$403,Flux_detail!$N$2:$N$403,$A18,Flux_detail!$B$2:$B$403,C$4) | D18: =SUMIFS(Flux_detail!$K$2:$K$403,Flux_detail!$N$2:$N$403,$A18,Flux_detail!$B$2:$B$403,D$4) | E18: =SUMIFS(Flux_detail!$K$2:$K$403,Flux_detail!$N$2:$N$403,$A18,Flux_detail!$B$2:$B$403,E$4) | F18: =SUMIFS(Flux_detail!$K$2:$K$403,Flux_detail!$N$2:$N$403,$A18,Flux_detail!$B$2:$B$403,F$4) | G18: =SUMIFS(Flux_detail!$K$2:$K$403,Flux_detail!$N$2:$N$403,$A18,Flux_detail!$B$2:$B$403,G$4) | H18: =SUMIFS(Flux_detail!$K$2:$K$403,Flux_detail!$N$2:$N$403,$A18,Flux_detail!$B$2:$B$403,H$4) | I18: =SUMIFS(Flux_detail!$K$2:$K$403,Flux_detail!$N$2:$N$403,$A18,Flux_detail!$B$2:$B$403,I$4) | ... BA18: =SUMIFS(Flux_detail!$K$2:$K$403,Flux_detail!$N$2:$N$403,$A18,Flux_detail!$B$2:$B$403,BA$4)
A19: Associés et groupe | B19: =SUMIFS(Flux_detail!$K$2:$K$403,Flux_detail!$N$2:$N$403,$A19,Flux_detail!$B$2:$B$403,B$4) | C19: =SUMIFS(Flux_detail!$K$2:$K$403,Flux_detail!$N$2:$N$403,$A19,Flux_detail!$B$2:$B$403,C$4) | D19: =SUMIFS(Flux_detail!$K$2:$K$403,Flux_detail!$N$2:$N$403,$A19,Flux_detail!$B$2:$B$403,D$4) | E19: =SUMIFS(Flux_detail!$K$2:$K$403,Flux_detail!$N$2:$N$403,$A19,Flux_detail!$B$2:$B$403,E$4) | F19: =SUMIFS(Flux_detail!$K$2:$K$403,Flux_detail!$N$2:$N$403,$A19,Flux_detail!$B$2:$B$403,F$4) | G19: =SUMIFS(Flux_detail!$K$2:$K$403,Flux_detail!$N$2:$N$403,$A19,Flux_detail!$B$2:$B$403,G$4) | H19: =SUMIFS(Flux_detail!$K$2:$K$403,Flux_detail!$N$2:$N$403,$A19,Flux_detail!$B$2:$B$403,H$4) | I19: =SUMIFS(Flux_detail!$K$2:$K$403,Flux_detail!$N$2:$N$403,$A19,Flux_detail!$B$2:$B$403,I$4) | ... BA19: =SUMIFS(Flux_detail!$K$2:$K$403,Flux_detail!$N$2:$N$403,$A19,Flux_detail!$B$2:$B$403,BA$4)
A20: Total flux de financement | B20: =SUMIFS(Flux_detail!$K$2:$K$403,Flux_detail!$O$2:$O$403,"FIN",Flux_detail!$B$2:$B$403,B$4) | C20: =SUMIFS(Flux_detail!$K$2:$K$403,Flux_detail!$O$2:$O$403,"FIN",Flux_detail!$B$2:$B$403,C$4) | D20: =SUMIFS(Flux_detail!$K$2:$K$403,Flux_detail!$O$2:$O$403,"FIN",Flux_detail!$B$2:$B$403,D$4) | E20: =SUMIFS(Flux_detail!$K$2:$K$403,Flux_detail!$O$2:$O$403,"FIN",Flux_detail!$B$2:$B$403,E$4) | F20: =SUMIFS(Flux_detail!$K$2:$K$403,Flux_detail!$O$2:$O$403,"FIN",Flux_detail!$B$2:$B$403,F$4) | G20: =SUMIFS(Flux_detail!$K$2:$K$403,Flux_detail!$O$2:$O$403,"FIN",Flux_detail!$B$2:$B$403,G$4) | H20: =SUMIFS(Flux_detail!$K$2:$K$403,Flux_detail!$O$2:$O$403,"FIN",Flux_detail!$B$2:$B$403,H$4) | I20: =SUMIFS(Flux_detail!$K$2:$K$403,Flux_detail!$O$2:$O$403,"FIN",Flux_detail!$B$2:$B$403,I$4) | ... BA20: =SUMIFS(Flux_detail!$K$2:$K$403,Flux_detail!$O$2:$O$403,"FIN",Flux_detail!$B$2:$B$403,BA$4)
A22: VARIATION DE TRÉSORERIE | B22: =SUMIFS(Flux_detail!$K$2:$K$403,Flux_detail!$B$2:$B$403,B$4) | C22: =SUMIFS(Flux_detail!$K$2:$K$403,Flux_detail!$B$2:$B$403,C$4) | D22: =SUMIFS(Flux_detail!$K$2:$K$403,Flux_detail!$B$2:$B$403,D$4) | E22: =SUMIFS(Flux_detail!$K$2:$K$403,Flux_detail!$B$2:$B$403,E$4) | F22: =SUMIFS(Flux_detail!$K$2:$K$403,Flux_detail!$B$2:$B$403,F$4) | G22: =SUMIFS(Flux_detail!$K$2:$K$403,Flux_detail!$B$2:$B$403,G$4) | H22: =SUMIFS(Flux_detail!$K$2:$K$403,Flux_detail!$B$2:$B$403,H$4) | I22: =SUMIFS(Flux_detail!$K$2:$K$403,Flux_detail!$B$2:$B$403,I$4) | ... BA22: =SUMIFS(Flux_detail!$K$2:$K$403,Flux_detail!$B$2:$B$403,BA$4)
A24: Moyenne hebdomadaire des 13 dernières semaines | B24: =AVERAGE(AO22:BA22)
A25: Moyenne hebdomadaire des 52 semaines | B25: =AVERAGE(B22:BA22)

Sheet Solde_quotidien
A1: Solde bancaire quotidien (tous comptes)
A2: Flux du jour et solde reconstitués depuis le FEC. Le point bas quotidien est la référence pour le besoin de trésorerie, pas le solde de fin de mois.
A4: Date | B4: Flux du jour | C4: Solde bancaire | D4: Mois | E4: Exercice | F4: Fonds en transit (58) | G4: Solde disponible | I4: Mois | J4: Solde bancaire fin de mois | K4: Point bas (disponible) | L4: Date du point bas | M4: Solde moyen (disponible)
A5: 45292 | B5: =SUMIFS(Flux_detail!$K$2:$K$403,Flux_detail!$A$2:$A$403,A5) | C5: =85000+B5 | D5: 2024-01 | E5: 2024 | F5: 0 | G5: =C5+F5 | I5: 2024-01 | J5: =INDEX($C$5:$C$735,MATCH(I5,$D$5:$D$735,1)) | K5: =_xlfn.MINIFS($G$5:$G$735,$D$5:$D$735,I5) | L5: 45301 | M5: =AVERAGEIFS($G$5:$G$735,$D$5:$D$735,I5)
A6: 45293 | B6: =SUMIFS(Flux_detail!$K$2:$K$403,Flux_detail!$A$2:$A$403,A6) | C6: =C5+B6 | D6: 2024-01 | E6: 2024 | F6: 0 | G6: =C6+F6 | I6: 2024-02 | J6: =INDEX($C$5:$C$735,MATCH(I6,$D$5:$D$735,1)) | K6: =_xlfn.MINIFS($G$5:$G$735,$D$5:$D$735,I6) | L6: 45337 | M6: =AVERAGEIFS($G$5:$G$735,$D$5:$D$735,I6)
A7: 45294 | B7: =SUMIFS(Flux_detail!$K$2:$K$403,Flux_detail!$A$2:$A$403,A7) | C7: =C6+B7 | D7: 2024-01 | E7: 2024 | F7: 0 | G7: =C7+F7 | I7: 2024-03 | J7: =INDEX($C$5:$C$735,MATCH(I7,$D$5:$D$735,1)) | K7: =_xlfn.MINIFS($G$5:$G$735,$D$5:$D$735,I7) | L7: 45382 | M7: =AVERAGEIFS($G$5:$G$735,$D$5:$D$735,I7)
A8: 45295 | B8: =SUMIFS(Flux_detail!$K$2:$K$403,Flux_detail!$A$2:$A$403,A8) | C8: =C7+B8 | D8: 2024-01 | E8: 2024 | F8: 0 | G8: =C8+F8 | I8: 2024-04 | J8: =INDEX($C$5:$C$735,MATCH(I8,$D$5:$D$735,1)) | K8: =_xlfn.MINIFS($G$5:$G$735,$D$5:$D$735,I8) | L8: 45392 | M8: =AVERAGEIFS($G$5:$G$735,$D$5:$D$735,I8)
A9: 45296 | B9: =SUMIFS(Flux_detail!$K$2:$K$403,Flux_detail!$A$2:$A$403,A9) | C9: =C8+B9 | D9: 2024-01 | E9: 2024 | F9: 0 | G9: =C9+F9 | I9: 2024-05 | J9: =INDEX($C$5:$C$735,MATCH(I9,$D$5:$D$735,1)) | K9: =_xlfn.MINIFS($G$5:$G$735,$D$5:$D$735,I9) | L9: 45443 | M9: =AVERAGEIFS($G$5:$G$735,$D$5:$D$735,I9)
A10: 45297 | B10: =SUMIFS(Flux_detail!$K$2:$K$403,Flux_detail!$A$2:$A$403,A10) | C10: =C9+B10 | D10: 2024-01 | E10: 2024 | F10: 0 | G10: =C10+F10 | I10: 2024-06 | J10: =INDEX($C$5:$C$735,MATCH(I10,$D$5:$D$735,1)) | K10: =_xlfn.MINIFS($G$5:$G$735,$D$5:$D$735,I10) | L10: 45444 | M10: =AVERAGEIFS($G$5:$G$735,$D$5:$D$735,I10)
A11: 45298 | B11: =SUMIFS(Flux_detail!$K$2:$K$403,Flux_detail!$A$2:$A$403,A11) | C11: =C10+B11 | D11: 2024-01 | E11: 2024 | F11: 0 | G11: =C11+F11 | I11: 2024-07 | J11: =INDEX($C$5:$C$735,MATCH(I11,$D$5:$D$735,1)) | K11: =_xlfn.MINIFS($G$5:$G$735,$D$5:$D$735,I11) | L11: 45504 | M11: =AVERAGEIFS($G$5:$G$735,$D$5:$D$735,I11)
A12: 45299 | B12: =SUMIFS(Flux_detail!$K$2:$K$403,Flux_detail!$A$2:$A$403,A12) | C12: =C11+B12 | D12: 2024-01 | E12: 2024 | F12: 0 | G12: =C12+F12 | I12: 2024-08 | J12: =INDEX($C$5:$C$735,MATCH(I12,$D$5:$D$735,1)) | K12: =_xlfn.MINIFS($G$5:$G$735,$D$5:$D$735,I12) | L12: 45519 | M12: =AVERAGEIFS($G$5:$G$735,$D$5:$D$735,I12)
A13: 45300 | B13: =SUMIFS(Flux_detail!$K$2:$K$403,Flux_detail!$A$2:$A$403,A13) | C13: =C12+B13 | D13: 2024-01 | E13: 2024 | F13: 0 | G13: =C13+F13 | I13: 2024-09 | J13: =INDEX($C$5:$C$735,MATCH(I13,$D$5:$D$735,1)) | K13: =_xlfn.MINIFS($G$5:$G$735,$D$5:$D$735,I13) | L13: 45565 | M13: =AVERAGEIFS($G$5:$G$735,$D$5:$D$735,I13)
A14: 45301 | B14: =SUMIFS(Flux_detail!$K$2:$K$403,Flux_detail!$A$2:$A$403,A14) | C14: =C13+B14 | D14: 2024-01 | E14: 2024 | F14: 0 | G14: =C14+F14 | I14: 2024-10 | J14: =INDEX($C$5:$C$735,MATCH(I14,$D$5:$D$735,1)) | K14: =_xlfn.MINIFS($G$5:$G$735,$D$5:$D$735,I14) | L14: 45596 | M14: =AVERAGEIFS($G$5:$G$735,$D$5:$D$735,I14)
A15: 45302 | B15: =SUMIFS(Flux_detail!$K$2:$K$403,Flux_detail!$A$2:$A$403,A15) | C15: =C14+B15 | D15: 2024-01 | E15: 2024 | F15: 0 | G15: =C15+F15 | I15: 2024-11 | J15: =INDEX($C$5:$C$735,MATCH(I15,$D$5:$D$735,1)) | K15: =_xlfn.MINIFS($G$5:$G$735,$D$5:$D$735,I15) | L15: 45606 | M15: =AVERAGEIFS($G$5:$G$735,$D$5:$D$735,I15)
A16: 45303 | B16: =SUMIFS(Flux_detail!$K$2:$K$403,Flux_detail!$A$2:$A$403,A16) | C16: =C15+B16 | D16: 2024-01 | E16: 2024 | F16: 0 | G16: =C16+F16 | I16: 2024-12 | J16: =INDEX($C$5:$C$735,MATCH(I16,$D$5:$D$735,1)) | K16: =_xlfn.MINIFS($G$5:$G$735,$D$5:$D$735,I16) | L16: 45657 | M16: =AVERAGEIFS($G$5:$G$735,$D$5:$D$735,I16)
A17: 45304 | B17: =SUMIFS(Flux_detail!$K$2:$K$403,Flux_detail!$A$2:$A$403,A17) | C17: =C16+B17 | D17: 2024-01 | E17: 2024 | F17: 0 | G17: =C17+F17 | I17: 2025-01 | J17: =INDEX($C$5:$C$735,MATCH(I17,$D$5:$D$735,1)) | K17: =_xlfn.MINIFS($G$5:$G$735,$D$5:$D$735,I17) | L17: 45688 | M17: =AVERAGEIFS($G$5:$G$735,$D$5:$D$735,I17)
... A28: 45315 | B28: =SUMIFS(Flux_detail!$K$2:$K$403,Flux_detail!$A$2:$A$403,A28) | C28: =C27+B28 | D28: 2024-01 | E28: 2024 | F28: 0 | G28: =C28+F28 | I28: 2025-12 | J28: =INDEX($C$5:$C$735,MATCH(I28,$D$5:$D$735,1)) | K28: =_xlfn.MINIFS($G$5:$G$735,$D$5:$D$735,I28) | L28: 46022 | M28: =AVERAGEIFS($G$5:$G$735,$D$5:$D$735,I28)
A29: 45316 | B29: =SUMIFS(Flux_detail!$K$2:$K$403,Flux_detail!$A$2:$A$403,A29) | C29: =C28+B29 | D29: 2024-01 | E29: 2024 | F29: 0 | G29: =C29+F29
A30: 45317 | B30: =SUMIFS(Flux_detail!$K$2:$K$403,Flux_detail!$A$2:$A$403,A30) | C30: =C29+B30 | D30: 2024-01 | E30: 2024 | F30: 0 | G30: =C30+F30 | I30: Solde disponible = solde bancaire + fonds en transit (virements sortis d'un compte, pas encore arrivés sur l'autre). Le point bas se lit sur le disponible.
A31: 45318 | B31: =SUMIFS(Flux_detail!$K$2:$K$403,Flux_detail!$A$2:$A$403,A31) | C31: =C30+B31 | D31: 2024-01 | E31: 2024 | F31: 0 | G31: =C31+F31
A32: 45319 | B32: =SUMIFS(Flux_detail!$K$2:$K$403,Flux_detail!$A$2:$A$403,A32) | C32: =C31+B32 | D32: 2024-01 | E32: 2024 | F32: 0 | G32: =C32+F32
A33: 45320 | B33: =SUMIFS(Flux_detail!$K$2:$K$403,Flux_detail!$A$2:$A$403,A33) | C33: =C32+B33 | D33: 2024-01 | E33: 2024 | F33: 0 | G33: =C33+F33
A34: 45321 | B34: =SUMIFS(Flux_detail!$K$2:$K$403,Flux_detail!$A$2:$A$403,A34) | C34: =C33+B34 | D34: 2024-01 | E34: 2024 | F34: 0 | G34: =C34+F34
A35: 45322 | B35: =SUMIFS(Flux_detail!$K$2:$K$403,Flux_detail!$A$2:$A$403,A35) | C35: =C34+B35 | D35: 2024-01 | E35: 2024 | F35: 0 | G35: =C35+F35
A36: 45323 | B36: =SUMIFS(Flux_detail!$K$2:$K$403,Flux_detail!$A$2:$A$403,A36) | C36: =C35+B36 | D36: 2024-02 | E36: 2024 | F36: 0 | G36: =C36+F36
A37: 45324 | B37: =SUMIFS(Flux_detail!$K$2:$K$403,Flux_detail!$A$2:$A$403,A37) | C37: =C36+B37 | D37: 2024-02 | E37: 2024 | F37: 0 | G37: =C37+F37
A38: 45325 | B38: =SUMIFS(Flux_detail!$K$2:$K$403,Flux_detail!$A$2:$A$403,A38) | C38: =C37+B38 | D38: 2024-02 | E38: 2024 | F38: 0 | G38: =C38+F38
A39: 45326 | B39: =SUMIFS(Flux_detail!$K$2:$K$403,Flux_detail!$A$2:$A$403,A39) | C39: =C38+B39 | D39: 2024-02 | E39: 2024 | F39: 0 | G39: =C39+F39
A40: 45327 | B40: =SUMIFS(Flux_detail!$K$2:$K$403,Flux_detail!$A$2:$A$403,A40) | C40: =C39+B40 | D40: 2024-02 | E40: 2024 | F40: 0 | G40: =C40+F40
A41: 45328 | B41: =SUMIFS(Flux_detail!$K$2:$K$403,Flux_detail!$A$2:$A$403,A41) | C41: =C40+B41 | D41: 2024-02 | E41: 2024 | F41: 0 | G41: =C41+F41
A42: 45329 | B42: =SUMIFS(Flux_detail!$K$2:$K$403,Flux_detail!$A$2:$A$403,A42) | C42: =C41+B42 | D42: 2024-02 | E42: 2024 | F42: 0 | G42: =C42+F42
... A370: 45657 | B370: =SUMIFS(Flux_detail!$K$2:$K$403,Flux_detail!$A$2:$A$403,A370) | C370: =C369+B370 | D370: 2024-12 | E370: 2024 | F370: 0 | G370: =C370+F370
A371: 45658 | B371: =SUMIFS(Flux_detail!$K$2:$K$403,Flux_detail!$A$2:$A$403,A371) | C371: =111111.24+B371 | D371: 2025-01 | E371: 2025 | F371: 0 | G371: =C371+F371
A372: 45659 | B372: =SUMIFS(Flux_detail!$K$2:$K$403,Flux_detail!$A$2:$A$403,A372) | C372: =C371+B372 | D372: 2025-01 | E372: 2025 | F372: 0 | G372: =C372+F372
A373: 45660 | B373: =SUMIFS(Flux_detail!$K$2:$K$403,Flux_detail!$A$2:$A$403,A373) | C373: =C372+B373 | D373: 2025-01 | E373: 2025 | F373: 0 | G373: =C373+F373
A374: 45661 | B374: =SUMIFS(Flux_detail!$K$2:$K$403,Flux_detail!$A$2:$A$403,A374) | C374: =C373+B374 | D374: 2025-01 | E374: 2025 | F374: 0 | G374: =C374+F374
A375: 45662 | B375: =SUMIFS(Flux_detail!$K$2:$K$403,Flux_detail!$A$2:$A$403,A375) | C375: =C374+B375 | D375: 2025-01 | E375: 2025 | F375: 0 | G375: =C375+F375
A376: 45663 | B376: =SUMIFS(Flux_detail!$K$2:$K$403,Flux_detail!$A$2:$A$403,A376) | C376: =C375+B376 | D376: 2025-01 | E376: 2025 | F376: 0 | G376: =C376+F376
A377: 45664 | B377: =SUMIFS(Flux_detail!$K$2:$K$403,Flux_detail!$A$2:$A$403,A377) | C377: =C376+B377 | D377: 2025-01 | E377: 2025 | F377: 0 | G377: =C377+F377
A378: 45665 | B378: =SUMIFS(Flux_detail!$K$2:$K$403,Flux_detail!$A$2:$A$403,A378) | C378: =C377+B378 | D378: 2025-01 | E378: 2025 | F378: 0 | G378: =C378+F378
...

Sheet Delais
A1: Délais réels d'encaissement et de paiement
A2: Calculés sur les factures lettrées avec un règlement bancaire : date de pièce de la facture → date du règlement, pondéré par les montants. Valeurs calculées par l'application.
A4: 2024 — Clients : délai d'encaissement : 37 jours en moyenne pondérée (56 lettrages, 2 241 761 €)
A5: Trimestre de règlement | B5: Délai moyen (jours) | C5: Montant réglé
A6: 2024-T1 | B6: 31 | C6: 353472
A7: 2024-T2 | B7: 40 | C7: 643203
A8: 2024-T3 | B8: 38 | C8: 632247
A9: 2024-T4 | B9: 37 | C9: 612839
A11: Tiers (15 premiers en volume) | B11: Montant réglé | C11: Délai (jours) | D11: Nb
A12: Residence Bel Air | B12: 387556 | C12: 37 | D12: 9
A13: Agence Mobilis | B13: 321775 | C13: 40 | D13: 8
A14: Clinique du Parc | B14: 315491 | C14: 39 | D14: 8
A15: Cabinet Varenne Associes | B15: 299328 | C15: 36 | D15: 7
A16: Coworking Atelier 9 | B16: 292816 | C16: 38 | D16: 7
A17: Hotel Les Tilleuls | B17: 283521 | C17: 36 | D17: 8
A18: Restaurant Le Comptoir | B18: 275105 | C18: 35 | D18: 7
A19: Boutique Hetre et Chene | B19: 66170 | C19: 30 | D19: 2
A22: 2024 — Fournisseurs : délai de paiement : 47 jours en moyenne pondérée (70 lettrages, 1 119 606 €)
A23: Trimestre de règlement | B23: Délai moyen (jours) | C23: Montant réglé
A24: 2024-T1 | B24: 38 | C24: 198333
A25: 2024-T2 | B25: 46 | C25: 269806
A26: 2024-T3 | B26: 50 | C26: 318432
A27: 2024-T4 | B27: 50 | C27: 333035
A29: Tiers (15 premiers en volume) | B29: Montant réglé | C29: Délai (jours) | D29: Nb
A30: Scierie du Nord | B30: 471982 | C30: 50 | D30: 14
A31: Quincaillerie Pro Est | B31: 296051 | C31: 51 | D31: 8
A32: Vernis et Finitions | B32: 148178 | C32: 53 | D32: 6
A33: SCI Les Halles | B33: 119200 | C33: 30 | D33: 12
A34: Energie Plus | B34: 44260 | C34: 30 | D34: 12
A35: Cabinet Comptable Exemple | B35: 21600 | C35: 31 | D35: 3
A36: Assurances Mutuelles Exemple | B36: 12000 | C36: 31 | D36: 4
A37: Telecom Pro | B37: 6336 | C37: 30 | D37: 11
A40: 2025 — Clients : délai d'encaissement : 55 jours en moyenne pondérée (46 lettrages, 1 566 782 €)
A41: Trimestre de règlement | B41: Délai moyen (jours) | C41: Montant réglé
A42: 2025-T1 | B42: 34 | C42: 257900
A43: 2025-T2 | B43: 61 | C43: 286729
A44: 2025-T3 | B44: 57 | C44: 570112
A45: 2025-T4 | B45: 62 | C45: 452040
A47: Tiers (15 premiers en volume) | B47: Montant réglé | C47: Délai (jours) | D47: Nb
A48: Coworking Atelier 9 | B48: 334739 | C48: 54 | D48: 10
...

Sheet Recurrences
A1: Décaissements récurrents — 12 derniers mois de 2025
A2: Base du calendrier des décaissements du prévisionnel. Jour type = jour du mois qui concentre le plus de montants. Valeurs calculées par l'application.
A4: Nature ou tiers | B4: Type | C4: Mois avec flux | D4: Moyenne mensuelle (sur 12 mois) | E4: Jour type | F4: Dernier montant | G4: Dernière date
A5: Salaires et personnel | B5: nature | C5: 12 / 12 | D5: -39098.84 | E5: 31 | F5: -38416.44 | G5: 46022
A6: Charges sociales | B6: nature | C6: 9 / 12 | D6: -24164.07 | E6: 15 | F6: -31562.21 | G6: 45915
A7: TVA | B7: nature | C7: 12 / 12 | D7: -10646.02 | E7: 20 | F7: -11227.16 | G7: 46011
A8: Impôt sur les sociétés | B8: nature | C8: 1 / 12 | D8: -755.59 | E8: 15 | F8: -9067.03 | G8: 45762
A9: Emprunts - capital | B9: nature | C9: 12 / 12 | D9: -2000 | E9: 10 | F9: -2000 | G9: 46001
A10: Intérêts et charges financières | B10: nature | C10: 12 / 12 | D10: -183.33 | E10: 10 | F10: -146.67 | G10: 46001
A11: Quincaillerie Pro Est | B11: tiers | C11: 7 / 12 | D11: -25624.73 | E11: 14 | F11: -26072.11 | G11: 46020
A12: Scierie du Nord | B12: tiers | C12: 7 / 12 | D12: -21148.4 | E12: 11 | F12: -15005.32 | G12: 46006
A13: Vernis et Finitions | B13: tiers | C13: 8 / 12 | D13: -17423.02 | E13: 24 | F13: -25951.42 | G13: 45993
A14: SCI Les Halles | B14: tiers | C14: 12 / 12 | D14: -10200 | E14: 4 | F14: -10200 | G14: 45996
A15: Energie Plus | B15: tiers | C15: 12 / 12 | D15: -3529.57 | E15: 4 | F15: -3481.04 | G15: 45996
A16: Telecom Pro | B16: tiers | C16: 12 / 12 | D16: -576 | E16: 4 | F16: -576 | G16: 45996

Sheet Categories
A1: Catégories de flux
A2: Bloc de chaque catégorie. Pour reclasser un flux, utiliser la colonne « Surcharge » de Flux_detail (liste ci-dessous).
A4: Catégorie | B4: Bloc | C4: Libellé du bloc
A5: Clients | B5: EXPL | C5: Flux d'exploitation
A6: Clients - avances et avoirs | B6: EXPL | C6: Flux d'exploitation
A7: Subventions et autres produits | B7: EXPL | C7: Flux d'exploitation
A8: Produits exceptionnels | B8: EXPL | C8: Flux d'exploitation
A9: Fournisseurs et charges externes | B9: EXPL | C9: Flux d'exploitation
A10: Frais bancaires | B10: EXPL | C10: Flux d'exploitation
A11: Salaires et personnel | B11: EXPL | C11: Flux d'exploitation
A12: Prélèvement à la source | B12: EXPL | C12: Flux d'exploitation
A13: Charges sociales | B13: EXPL | C13: Flux d'exploitation
A14: TVA | B14: EXPL | C14: Flux d'exploitation
A15: Impôt sur les sociétés | B15: EXPL | C15: Flux d'exploitation
... A35: Virements internes (transit groupé) | B35: INT | C35: Virements internes
A37: Règles d'affectation (compte de contrepartie de l'écriture de banque, racine la plus longue)
A38: Racine | B38: Catégorie | C38: Bloc
A39: 1 | B39: Autres financements | C39: FIN
A40: 10 | B40: Capital et subventions d'investissement | C40: FIN
A41: 13 | B41: Capital et subventions d'investissement | C41: FIN
A42: 16 | B42: Emprunts - capital | C42: FIN
A43: 17 | B43: Emprunts - capital | C43: FIN
A44: 2 | B44: Investissements | C44: INV
A45: 3 | B45: Autres | C45: NA
A46: 40 | B46: Fournisseurs et charges externes | C46: EXPL
A47: 404 | B47: Investissements | C47: INV
A48: 405 | B48: Investissements | C48: INV
A49: 41 | B49: Clients | C49: EXPL
... A88: 79 | B88: Subventions et autres produits | C88: EXPL
A90: Compte dont le libellé contient FACTOR, AFFACTURAGE, COFACREDIT ou EUROFACTOR → « Encaissements via le factor » (bloc exploitation : ce sont les créances cédées, avancées par le factor). Les comptes courants du factor tenus en 51x sont exclus de la trésorerie bancaire.
A91: Compte 58 : apparié à l'autre banque (virement interne), sinon à l'écriture hors banque qui le solde (catégorie de ses contreparties), sinon « Transit 58 non rapproché ».
A92: Écriture de banque à plusieurs contreparties : chaque contrepartie donne un flux de son propre montant (la somme égale le mouvement de banque).

Sheet Flux_detail
A1: Date | B1: Semaine | C1: Mois | D1: Exercice | E1: Banque | F1: Journal | G1: N° écriture | H1: Contrepartie | I1: Libellé | J1: Tiers | K1: Montant | L1: Catégorie proposée | M1: Surcharge | N1: Catégorie retenue | O1: Bloc
A2: 45301 | B2: 2024-S02 | C2: 2024-01 | D2: 2024 | E2: 512000 | F2: BQ | G2: BQ00002 | H2: 164000 | I2: Echeance emprunt 01/2024 | K2: -2000 | L2: Emprunts - capital | N2: =IF(M2<>"",M2,L2) | O2: =IFERROR(INDEX(Categories!$B$5:$B$35,MATCH(N2,Categories!$A$5:$A$35,0)),"NA")
A3: 45301 | B3: 2024-S02 | C3: 2024-01 | D3: 2024 | E3: 512000 | F3: BQ | G3: BQ00002 | H3: 661100 | I3: Echeance emprunt 01/2024 | K3: -300 | L3: Intérêts et charges financières | N3: =IF(M3<>"",M3,L3) | O3: =IFERROR(INDEX(Categories!$B$5:$B$35,MATCH(N3,Categories!$A$5:$A$35,0)),"NA")
A4: 45301 | B4: 2024-S02 | C4: 2024-01 | D4: 2024 | E4: 512000 | F4: BQ | G4: BQ00120 | H4: 401000 | I4: Reglement fournisseur Scierie du Nord AN2024 | J4: Scierie du Nord | K4: -28000 | L4: Fournisseurs et charges externes | N4: =IF(M4<>"",M4,L4) | O4: =IFERROR(INDEX(Categories!$B$5:$B$35,MATCH(N4,Categories!$A$5:$A$35,0)),"NA")
A5: 45306 | B5: 2024-S03 | C5: 2024-01 | D5: 2024 | E5: 512000 | F5: BQ | G5: BQ00037 | H5: 431000 | I5: Reglement URSSAF 12/2023 | K5: -18000 | L5: Charges sociales | N5: =IF(M5<>"",M5,L5) | O5: =IFERROR(INDEX(Categories!$B$5:$B$35,MATCH(N5,Categories!$A$5:$A$35,0)),"NA")
A6: 45306 | B6: 2024-S03 | C6: 2024-01 | D6: 2024 | E6: 512000 | F6: BQ | G6: BQ00061 | H6: 411000 | I6: Reglement client Hotel Les Tilleuls AN2024 | J6: Hotel Les Tilleuls | K6: 30000 | L6: Clients | N6: =IF(M6<>"",M6,L6) | O6: =IFERROR(INDEX(Categories!$B$5:$B$35,MATCH(N6,Categories!$A$5:$A$35,0)),"NA")
A7: 45306 | B7: 2024-S03 | C7: 2024-01 | D7: 2024 | E7: 512000 | F7: BQ | G7: BQ00121 | H7: 401000 | I7: Reglement fournisseur Quincaillerie Pro Est AN2024 | J7: Quincaillerie Pro Est | K7: -12000 | L7: Fournisseurs et charges externes | N7: =IF(M7<>"",M7,L7) | O7: =IFERROR(INDEX(Categories!$B$5:$B$35,MATCH(N7,Categories!$A$5:$A$35,0)),"NA")
A8: 45309 | B8: 2024-S03 | C8: 2024-01 | D8: 2024 | E8: 512000 | F8: BQ | G8: BQ00062 | H8: 411000 | I8: Reglement client Residence Bel Air AN2024 | J8: Residence Bel Air | K8: 26000 | L8: Clients | N8: =IF(M8<>"",M8,L8) | O8: =IFERROR(INDEX(Categories!$B$5:$B$35,MATCH(N8,Categories!$A$5:$A$35,0)),"NA")
A9: 45309 | B9: 2024-S03 | C9: 2024-01 | D9: 2024 | E9: 512000 | F9: BQ | G9: BQ00122 | H9: 401000 | I9: Reglement fournisseur Vernis et Finitions AN2024 | J9: Vernis et Finitions | K9: -9000 | L9: Fournisseurs et charges externes | N9: =IF(M9<>"",M9,L9) | O9: =IFERROR(INDEX(Categories!$B$5:$B$35,MATCH(N9,Categories!$A$5:$A$35,0)),"NA")
A10: 45311 | B10: 2024-S03 | C10: 2024-01 | D10: 2024 | E10: 512000 | F10: BQ | G10: BQ00038 | H10: 445510 | I10: Reglement TVA 12/2023 | K10: -12000 | L10: TVA | N10: =IF(M10<>"",M10,L10) | O10: =IFERROR(INDEX(Categories!$B$5:$B$35,MATCH(N10,Categories!$A$5:$A$35,0)),"NA")
A11: 45313 | B11: 2024-S04 | C11: 2024-01 | D11: 2024 | E11: 512000 | F11: BQ | G11: BQ00063 | H11: 411000 | I11: Reglement client Cabinet Varenne Associes AN2024 | J11: Cabinet Varenne Associes | K11: 22000 | L11: Clients | N11: =IF(M11<>"",M11,L11) | O11: =IFERROR(INDEX(Categories!$B$5:$B$35,MATCH(N11,Categories!$A$5:$A$35,0)),"NA")
A12: 45313 | B12: 2024-S04 | C12: 2024-01 | D12: 2024 | E12: 512000 | F12: BQ | G12: BQ00123 | H12: 401000 | I12: Reglement fournisseur Energie Plus AN2024 | J12: Energie Plus | K12: -4000 | L12: Fournisseurs et charges externes | N12: =IF(M12<>"",M12,L12) | O12: =IFERROR(INDEX(Categories!$B$5:$B$35,MATCH(N12,Categories!$A$5:$A$35,0)),"NA")
A13: 45315 | B13: 2024-S04 | C13: 2024-01 | D13: 2024 | E13: 512000 | F13: BQ | G13: BQ00064 | H13: 411000 | I13: Reglement client Clinique du Parc AN2024 | J13: Clinique du Parc | K13: 24000 | L13: Clients | N13: =IF(M13<>"",M13,L13) | O13: =IFERROR(INDEX(Categories!$B$5:$B$35,MATCH(N13,Categories!$A$5:$A$35,0)),"NA")
A14: 45317 | B14: 2024-S04 | C14: 2024-01 | D14: 2024 | E14: 512000 | F14: BQ | G14: BQ00124 | H14: 401000 | I14: Reglement fournisseur SCI Les Halles AN2024 | J14: SCI Les Halles | K14: -7000 | L14: Fournisseurs et charges externes | N14: =IF(M14<>"",M14,L14) | O14: =IFERROR(INDEX(Categories!$B$5:$B$35,MATCH(N14,Categories!$A$5:$A$35,0)),"NA")
A15: 45320 | B15: 2024-S05 | C15: 2024-01 | D15: 2024 | E15: 512000 | F15: BQ | G15: BQ00065 | H15: 411000 | I15: Reglement client Coworking Atelier 9 AN2024 | J15: Coworking Atelier 9 | K15: 18000 | L15: Clients | N15: =IF(M15<>"",M15,L15) | O15: =IFERROR(INDEX(Categories!$B$5:$B$35,MATCH(N15,Categories!$A$5:$A$35,0)),"NA")
A16: 45320 | B16: 2024-S05 | C16: 2024-01 | D16: 2024 | E16: 512000 | F16: BQ | G16: BQ00067 | H16: 411000 | I16: Reglement client Hotel Les Tilleuls FA2024-0002 | J16: Hotel Les Tilleuls | K16: 38532.72 | L16: Clients | N16: =IF(M16<>"",M16,L16) | O16: =IFERROR(INDEX(Categories!$B$5:$B$35,MATCH(N16,Categories!$A$5:$A$35,0)),"NA")
A17: 45322 | B17: 2024-S05 | C17: 2024-01 | D17: 2024 | E17: 512000 | F17: BQ | G17: BQ00001 | H17: 421000 | I17: Virement salaires 01/2024 | K17: -41123.78 | L17: Salaires et personnel | N17: =IF(M17<>"",M17,L17) | O17: =IFERROR(INDEX(Categories!$B$5:$B$35,MATCH(N17,Categories!$A$5:$A$35,0)),"NA")
A18: 45322 | B18: 2024-S05 | C18: 2024-01 | D18: 2024 | E18: 512000 | F18: BQ | G18: BQ00003 | H18: 627000 | I18: Frais bancaires 01/2024 | K18: -85 | L18: Frais bancaires | N18: =IF(M18<>"",M18,L18) | O18: =IFERROR(INDEX(Categories!$B$5:$B$35,MATCH(N18,Categories!$A$5:$A$35,0)),"NA")
A19: 45327 | B19: 2024-S06 | C19: 2024-02 | D19: 2024 | E19: 512000 | F19: BQ | G19: BQ00127 | H19: 401000 | I19: Reglement fournisseur SCI Les Halles F004-202401 | J19: SCI Les Halles | K19: -10200 | L19: Fournisseurs et charges externes | N19: =IF(M19<>"",M19,L19) | O19: =IFERROR(INDEX(Categories!$B$5:$B$35,MATCH(N19,Categories!$A$5:$A$35,0)),"NA")
A20: 45327 | B20: 2024-S06 | C20: 2024-02 | D20: 2024 | E20: 512000 | F20: BQ | G20: BQ00128 | H20: 401000 | I20: Reglement fournisseur Energie Plus F005-202401 | J20: Energie Plus | K20: -3036.68 | L20: Fournisseurs et charges externes | N20: =IF(M20<>"",M20,L20) | O20: =IFERROR(INDEX(Categories!$B$5:$B$35,MATCH(N20,Categories!$A$5:$A$35,0)),"NA")
A21: 45327 | B21: 2024-S06 | C21: 2024-02 | D21: 2024 | E21: 512000 | F21: BQ | G21: BQ00129 | H21: 401000 | I21: Reglement fournisseur Telecom Pro F008-202401 | J21: Telecom Pro | K21: -576 | L21: Fournisseurs et charges externes | N21: =IF(M21<>"",M21,L21) | O21: =IFERROR(INDEX(Categories!$B$5:$B$35,MATCH(N21,Categories!$A$5:$A$35,0)),"NA")
A22: 45327 | B22: 2024-S06 | C22: 2024-02 | D22: 2024 | E22: 512000 | F22: BQ | G22: BQ00130 | H22: 401000 | I22: Reglement fournisseur Assurances Mutuelles Exemple F006-202401 | J22: Assurances Mutuelles Exemple | K22: -3000 | L22: Fournisseurs et charges externes | N22: =IF(M22<>"",M22,L22) | O22: =IFERROR(INDEX(Categories!$B$5:$B$35,MATCH(N22,Categories!$A$5:$A$35,0)),"NA")
A23: 45332 | B23: 2024-S06 | C23: 2024-02 | D23: 2024 | E23: 512000 | F23: BQ | G23: BQ00005 | H23: 164000 | I23: Echeance emprunt 02/2024 | K23: -2000 | L23: Emprunts - capital | N23: =IF(M23<>"",M23,L23) | O23: =IFERROR(INDEX(Categories!$B$5:$B$35,MATCH(N23,Categories!$A$5:$A$35,0)),"NA")
A24: 45332 | B24: 2024-S06 | C24: 2024-02 | D24: 2024 | E24: 512000 | F24: BQ | G24: BQ00005 | H24: 661100 | I24: Echeance emprunt 02/2024 | K24: -293.33 | L24: Intérêts et charges financières | N24: =IF(M24<>"",M24,L24) | O24: =IFERROR(INDEX(Categories!$B$5:$B$35,MATCH(N24,Categories!$A$5:$A$35,0)),"NA")
A25: 45337 | B25: 2024-S07 | C25: 2024-02 | D25: 2024 | E25: 512000 | F25: BQ | G25: BQ00039 | H25: 431000 | I25: Reglement URSSAF 01/2024 | K25: -33742.58 | L25: Charges sociales | N25: =IF(M25<>"",M25,L25) | O25: =IFERROR(INDEX(Categories!$B$5:$B$35,MATCH(N25,Categories!$A$5:$A$35,0)),"NA")
A26: 45338 | B26: 2024-S07 | C26: 2024-02 | D26: 2024 | E26: 512000 | F26: BQ | G26: BQ00070 | H26: 411000 | I26: Reglement client Boutique Hetre et Chene FA2024-0005 | J26: Boutique Hetre et Chene | K26: 22023.36 | L26: Clients | N26: =IF(M26<>"",M26,L26) | O26: =IFERROR(INDEX(Categories!$B$5:$B$35,MATCH(N26,Categories!$A$5:$A$35,0)),"NA")
A27: 45341 | B27: 2024-S08 | C27: 2024-02 | D27: 2024 | E27: 512000 | F27: BQ | G27: BQ00068 | H27: 411000 | I27: Reglement client Cabinet Varenne Associes FA2024-0003 | J27: Cabinet Varenne Associes | K27: 25702.04 | L27: Clients | N27: =IF(M27<>"",M27,L27) | O27: =IFERROR(INDEX(Categories!$B$5:$B$35,MATCH(N27,Categories!$A$5:$A$35,0)),"NA")
A28: 45341 | B28: 2024-S08 | C28: 2024-02 | D28: 2024 | E28: 512000 | F28: BQ | G28: BQ00069 | H28: 411000 | I28: Reglement client Hotel Les Tilleuls FA2024-0004 | J28: Hotel Les Tilleuls | K28: 22980.32 | L28: Clients | N28: =IF(M28<>"",M28,L28) | O28: =IFERROR(INDEX(Categories!$B$5:$B$35,MATCH(N28,Categories!$A$5:$A$35,0)),"NA")
A29: 45342 | B29: 2024-S08 | C29: 2024-02 | D29: 2024 | E29: 512000 | F29: BQ | G29: BQ00040 | H29: 445510 | I29: Reglement TVA 01/2024 | K29: -14131.22 | L29: TVA | N29: =IF(M29<>"",M29,L29) | O29: =IFERROR(INDEX(Categories!$B$5:$B$35,MATCH(N29,Categories!$A$5:$A$35,0)),"NA")
A30: 45342 | B30: 2024-S08 | C30: 2024-02 | D30: 2024 | E30: 512000 | F30: BQ | G30: BQ00071 | H30: 411000 | I30: Reglement client Restaurant Le Comptoir FA2024-0006 | J30: Restaurant Le Comptoir | K30: 38509.92 | L30: Clients | N30: =IF(M30<>"",M30,L30) | O30: =IFERROR(INDEX(Categories!$B$5:$B$35,MATCH(N30,Categories!$A$5:$A$35,0)),"NA")
A31: 45348 | B31: 2024-S09 | C31: 2024-02 | D31: 2024 | E31: 512000 | F31: BQ | G31: BQ00066 | H31: 411000 | I31: Reglement client Agence Mobilis FA2024-0001 | J31: Agence Mobilis | K31: 22251.64 | L31: Clients | N31: =IF(M31<>"",M31,L31) | O31: =IFERROR(INDEX(Categories!$B$5:$B$35,MATCH(N31,Categories!$A$5:$A$35,0)),"NA")
A32: 45351 | B32: 2024-S09 | C32: 2024-02 | D32: 2024 | E32: 512000 | F32: BQ | G32: BQ00004 | H32: 421000 | I32: Virement salaires 02/2024 | K32: -40186.76 | L32: Salaires et personnel | N32: =IF(M32<>"",M32,L32) | O32: =IFERROR(INDEX(Categories!$B$5:$B$35,MATCH(N32,Categories!$A$5:$A$35,0)),"NA")
A33: 45351 | B33: 2024-S09 | C33: 2024-02 | D33: 2024 | E33: 512000 | F33: BQ | G33: BQ00006 | H33: 627000 | I33: Frais bancaires 02/2024 | K33: -85 | L33: Frais bancaires | N33: =IF(M33<>"",M33,L33) | O33: =IFERROR(INDEX(Categories!$B$5:$B$35,MATCH(N33,Categories!$A$5:$A$35,0)),"NA")
A34: 45351 | B34: 2024-S09 | C34: 2024-02 | D34: 2024 | E34: 512000 | F34: BQ | G34: BQ00126 | H34: 401000 | I34: Reglement fournisseur Scierie du Nord F001-2024012 | J34: Scierie du Nord | K34: -31910.65 | L34: Fournisseurs et charges externes | N34: =IF(M34<>"",M34,L34) | O34: =IFERROR(INDEX(Categories!$B$5:$B$35,MATCH(N34,Categories!$A$5:$A$35,0)),"NA")
A35: 45357 | B35: 2024-S10 | C35: 2024-03 | D35: 2024 | E35: 512000 | F35: BQ | G35: BQ00133 | H35: 401000 | I35: Reglement fournisseur SCI Les Halles F004-202402 | J35: SCI Les Halles | K35: -10200 | L35: Fournisseurs et charges externes | N35: =IF(M35<>"",M35,L35) | O35: =IFERROR(INDEX(Categories!$B$5:$B$35,MATCH(N35,Categories!$A$5:$A$35,0)),"NA")
A36: 45357 | B36: 2024-S10 | C36: 2024-03 | D36: 2024 | E36: 512000 | F36: BQ | G36: BQ00134 | H36: 401000 | I36: Reglement fournisseur Energie Plus F005-202402 | J36: Energie Plus | K36: -3628.86 | L36: Fournisseurs et charges externes | N36: =IF(M36<>"",M36,L36) | O36: =IFERROR(INDEX(Categories!$B$5:$B$35,MATCH(N36,Categories!$A$5:$A$35,0)),"NA")
A37: 45357 | B37: 2024-S10 | C37: 2024-03 | D37: 2024 | E37: 512000 | F37: BQ | G37: BQ00135 | H37: 401000 | I37: Reglement fournisseur Telecom Pro F008-202402 | J37: Telecom Pro | K37: -576 | L37: Fournisseurs et charges externes | N37: =IF(M37<>"",M37,L37) | O37: =IFERROR(INDEX(Categories!$B$5:$B$35,MATCH(N37,Categories!$A$5:$A$35,0)),"NA")
A38: 45361 | B38: 2024-S10 | C38: 2024-03 | D38: 2024 | E38: 512000 | F38: BQ | G38: BQ00008 | H38: 164000 | I38: Echeance emprunt 03/2024 | K38: -2000 | L38: Emprunts - capital | N38: =IF(M38<>"",M38,L38) | O38: =IFERROR(INDEX(Categories!$B$5:$B$35,MATCH(N38,Categories!$A$5:$A$35,0)),"NA")
A39: 45361 | B39: 2024-S10 | C39: 2024-03 | D39: 2024 | E39: 512000 | F39: BQ | G39: BQ00008 | H39: 661100 | I39: Echeance emprunt 03/2024 | K39: -286.67 | L39: Intérêts et charges financières | N39: =IF(M39<>"",M39,L39) | O39: =IFERROR(INDEX(Categories!$B$5:$B$35,MATCH(N39,Categories!$A$5:$A$35,0)),"NA")
A40: 45366 | B40: 2024-S11 | C40: 2024-03 | D40: 2024 | E40: 512000 | F40: BQ | G40: BQ00041 | H40: 431000 | I40: Reglement URSSAF 02/2024 | K40: -32973.76 | L40: Charges sociales | N40: =IF(M40<>"",M40,L40) | O40: =IFERROR(INDEX(Categories!$B$5:$B$35,MATCH(N40,Categories!$A$5:$A$35,0)),"NA")
...
